<sdf version='1.6'>
  <model name='mouse_hind_leg'>
    <pose>0 0 0 0 0 0</pose>
    <link name="base">
      <kinematic>true</kinematic>
      <inertial>
        <mass>5000</mass>
      </inertial>
      <visual name="vis_plate_on_ground">
        <pose>0 0 0.01 0 0 0</pose>
        <geometry>
          <cylinder>
            <radius>0.8</radius>
            <length>0.02</length>
          </cylinder>
        </geometry>
        <material>
          <script>
            <uri>file://media/materials/scripts/gazebo.material</uri>
            <name>Gazebo/Grey</name>
          </script>
        </material>
      </visual>
      <visual name="vis_pole">
        <pose>-0.275 0 0.5 0 0 0</pose>
        <geometry>
          <box>
            <size>0.2 0.2 1</size>
          </box>
        </geometry>
        <material>
          <script>
            <uri>file://media/materials/scripts/gazebo.material</uri>
            <name>Gazebo/Grey</name>
          </script>
        </material>
      </visual>
      <collision name="col_plate_on_ground">
        <pose>0 0 0.01 0 0 0</pose>
        <geometry>
          <cylinder>
            <radius>0.8</radius>
            <length>0.02</length>
          </cylinder>
        </geometry>
      </collision>
      <collision name="col_pole">
        <pose>-0.275 0 0.5 0 0 0</pose>
        <geometry>
          <box>
            <size>0.2 0.2 1</size>
          </box>
        </geometry>
      </collision>
    </link>
    
    <link name="upper_link">
      <pose>0 0 1 -1.5708 0 0</pose>
      <self_collide>0</self_collide>
      <inertial>
        <pose>0 0 0.5 0 0 0</pose>
      </inertial>
      <visual name="vis_upper_joint">
        <pose>1.0 0 0 0 1.5708 0</pose>
        <geometry>
          <cylinder>
            <radius>0.02</radius>
            <length>2.5</length>
          </cylinder>
        </geometry>
        <material>
          <script>
            <uri>file://media/materials/scripts/gazebo.material</uri>
            <name>Gazebo/Grey</name>
          </script>
        </material>
      </visual>
     
      <collision name="col_upper_joint">
        <pose>1.0 0 0 0 1.5708 0</pose>
        <geometry>
          <cylinder>
            <radius>0.02</radius>
            <length>2.5</length>
          </cylinder>
        </geometry>
      </collision>
    </link>
    
    <!-- pin joint for upper link, at origin of upper link -->
    <joint name="upper_joint" type="revolute">
      <parent>base</parent>
      <child>upper_link</child>
      <axis>
        <xyz>1.0 0 0</xyz>
        <limit>
          <lower>-0.523599</lower>
          <upper>0.523599</upper>
        </limit>
        <dynamics>
          <damping>0.1</damping>
          <friction>0.05</friction>
          <spring_reference>0</spring_reference>
          <spring_stiffness>0</spring_stiffness>
        </dynamics>
        <use_parent_model_frame>true</use_parent_model_frame>
      </axis>
      <physics>
        <provide_feedback>true</provide_feedback>
      </physics>
    </joint>
    
    <link name='thigh_L_link'>
      <pose frame=''>2.35 0 1 0 0 0</pose>
      <inertial>
        <pose frame=''>0 -0.15 -0.1 0 0 0</pose>
        <mass>1</mass>
        <inertia>
          <ixx>1</ixx>
          <ixy>0</ixy>
          <ixz>0</ixz>
          <iyy>1</iyy>
          <iyz>0</iyz>
          <izz>1</izz>
        </inertia>
      </inertial>
      <collision name='thigh_L_link_collision'>
        <geometry>
          <mesh>
            <scale>1 1 1</scale>
            <uri>model://mouse_v2_model/collisions/COL_obj_thigh.L_convex_hull.dae</uri>
          </mesh>
        </geometry>
      </collision>
      <visual name='thigh_L_link_visual'>
        <geometry>
          <mesh>
            <scale>1 1 1</scale>
            <uri>model://mouse_v2_model/meshes/obj_thigh.L.dae</uri>
          </mesh>
        </geometry>
      </visual>
    </link>
    <joint name='thigh_L_joint' type='revolute'>
      <child>thigh_L_link</child>
      <parent>upper_link</parent>
      <axis>
        <xyz>1 1e-06 -2e-06</xyz>
        <limit>
          <lower>-0.523599</lower>
          <upper>0.523599</upper>
        </limit>
        <dynamics>
          <damping>0.1</damping>
          <friction>0.05</friction>
          <spring_reference>0</spring_reference>
          <spring_stiffness>0</spring_stiffness>
        </dynamics>
        <use_parent_model_frame>1</use_parent_model_frame>
      </axis>
      <physics>
        <provide_feedback>true</provide_feedback>
      </physics>
    </joint>
    
    <link name='shin_L_link'>
      <pose frame=''>2.35 0 0.8 0 0 0</pose>
      <inertial>
        <pose frame=''>0 -0.1 -0.05 0 -0 0</pose>
        <mass>2</mass>
        <inertia>
          <ixx>1</ixx>
          <ixy>0</ixy>
          <ixz>0</ixz>
          <iyy>1</iyy>
          <iyz>0</iyz>
          <izz>1</izz>
        </inertia>
      </inertial>
      <collision name='shin_L_link_collision'>
        <pose frame=''>-0.000663 0.009381 -0.006255 1e-06 0 -1e-06</pose>
        <geometry>
          <mesh>
            <scale>1 1 1</scale>
            <uri>model://mouse_v2_model/collisions/COL_obj_shin.L_convex_hull.dae</uri>
          </mesh>
        </geometry>
      </collision>
      <visual name='shin_L_link_visual'>
        <pose frame=''>-0.000663 0.009381 -0.006255 1e-06 0 -1e-06</pose>
        <geometry>
          <mesh>
            <scale>1 1 1</scale>
            <uri>model://mouse_v2_model/meshes/obj_shin.L.dae</uri>
          </mesh>
        </geometry>
      </visual>
    </link>
    <joint name='shin_L_joint' type='revolute'>
      <child>shin_L_link</child>
      <parent>thigh_L_link</parent>
      <axis>
        <xyz>1 1e-06 -2e-06</xyz>
        <limit>
          <lower>-0.78</lower>
          <upper>0.78</upper>
        </limit>
        <dynamics>
          <damping>0.1</damping>
          <friction>0.05</friction>
          <spring_reference>0.1</spring_reference>
          <spring_stiffness>0.5</spring_stiffness>
        </dynamics>
        <use_parent_model_frame>1</use_parent_model_frame>
      </axis>
      <physics>
        <provide_feedback>true</provide_feedback>
      </physics>
    </joint>
    
    <link name='shin_lower_L_link'>
      <pose frame=''>2.35 0 0.65 0 0 0</pose>
      <inertial>
        <pose frame=''>0 0 0 0 -0 0</pose>
        <mass>2</mass>
        <inertia>
          <ixx>1</ixx>
          <ixy>0</ixy>
          <ixz>0</ixz>
          <iyy>1</iyy>
          <iyz>0</iyz>
          <izz>1</izz>
        </inertia>
      </inertial>
      <collision name='shin_lower_L_link_collision'>
        <pose frame=''>0.000457 -0.007472 -0.000436 1e-06 0 -1e-06</pose>
        <geometry>
          <mesh>
            <scale>1 1 1</scale>
            <uri>model://mouse_v2_model/collisions/COL_obj_shin_lower.L_convex_hull.dae</uri>
          </mesh>
        </geometry>
      </collision>
      <visual name='shin_lower_L_link_visual'>
        <pose frame=''>0.000457 -0.007472 -0.000436 1e-06 0 -1e-06</pose>
        <geometry>
          <mesh>
            <scale>1 1 1</scale>
            <uri>model://mouse_v2_model/meshes/obj_shin_lower.L.dae</uri>
          </mesh>
        </geometry>
      </visual>
    </link>
    <joint name='shin_lower_L_joint' type='revolute'>
      <child>shin_lower_L_link</child>
      <parent>shin_L_link</parent>
      <axis>
        <xyz>1 1e-06 -2e-06</xyz>
        <limit>
          <lower>-1000000.0</lower>
          <upper>1000000.0</upper>
        </limit>
        <dynamics>
          <damping>0.1</damping>
          <friction>0.05</friction>
          <spring_reference>0.1</spring_reference>
          <spring_stiffness>0.5</spring_stiffness>
        </dynamics>
        <use_parent_model_frame>1</use_parent_model_frame>
      </axis>
      <physics>
        <provide_feedback>true</provide_feedback>
      </physics>
    </joint>
    
    <static>false</static>
    <self_collide>false</self_collide>
  </model>
</sdf>
