<?xml version="1.0" encoding="utf-8"?>
<robot name="cheesy5">
  <joint name="hips.001_joint" type="fixed">
    <origin rpy="0 -0 0" xyz="0 0 0"/>
    <parent link="root_link"/>
    <child link="hips.001_link"/>
    <axis xyz="0 0 1"/>
    <calibration falling="0.0" reference_position="0.0" rising="0.0"/>
    <dynamics damping="1.0"/>
    <limit effort="100.0" lower="1.0" upper="1.0" velocity="1.0"/>
  </joint>
  <joint name="joint_1_obj_hips.002_joint" type="revolute">
    <origin rpy="1.5707963705062866 -1.570796251296997 0" xyz="0.00015801030167024444 -0.004131013057175892 0.00016806355352727564"/>
    <parent link="hips.001_link"/>
    <child link="joint_1_obj_hips.002_link"/>
    <axis xyz="1 0 0"/>
    <calibration falling="0.0" reference_position="0.0" rising="0.0"/>
    <dynamics damping="1.0"/>
    <limit effort="100.0" lower="-0.2617993877991494" upper="0.2617993877991494" velocity="1.0"/>
  </joint>
  <joint name="hips.002_joint" type="revolute">
    <origin rpy="-1.5707963705062866 -0 -1.5707963705062866" xyz="1.5586901564558607e-08 8.958779229561506e-09 1.1734748691642296e-08"/>
    <parent link="joint_1_obj_hips.002_link"/>
    <child link="hips.002_link"/>
    <axis xyz="1 0 0"/>
    <calibration falling="0.0" reference_position="0.0" rising="0.0"/>
    <dynamics damping="1.0"/>
    <limit effort="100.0" lower="-0.2617993877991494" upper="0.2617993877991494" velocity="1.0"/>
  </joint>
  <joint name="joint_1_obj_hips.003_joint" type="revolute">
    <origin rpy="1.5707963705062866 -1.570796251296997 0" xyz="3.579280205289941e-08 -0.011548312094546986 -0.0002490862547607081"/>
    <parent link="hips.002_link"/>
    <child link="joint_1_obj_hips.003_link"/>
    <axis xyz="1 0 0"/>
    <calibration falling="0.0" reference_position="0.0" rising="0.0"/>
    <dynamics damping="1.0"/>
    <limit effort="100.0" lower="-0.2617993877991494" upper="0.2617993877991494" velocity="1.0"/>
  </joint>
  <joint name="hips.003_joint" type="revolute">
    <origin rpy="-1.5707963705062866 -0 -1.5707963705062866" xyz="3.021630082500817e-09 3.5743851234067676e-08 -2.9630180553291555e-08"/>
    <parent link="joint_1_obj_hips.003_link"/>
    <child link="hips.003_link"/>
    <axis xyz="1 0 0"/>
    <calibration falling="0.0" reference_position="0.0" rising="0.0"/>
    <dynamics damping="1.0"/>
    <limit effort="100.0" lower="-0.2617993877991494" upper="0.2617993877991494" velocity="1.0"/>
  </joint>
  <joint name="joint_1_obj_hips.004_joint" type="revolute">
    <origin rpy="1.5707963705062866 -1.570796251296997 0" xyz="8.908893897036055e-09 -0.012427024616445959 -0.00017526978441002178"/>
    <parent link="hips.003_link"/>
    <child link="joint_1_obj_hips.004_link"/>
    <axis xyz="1 0 0"/>
    <calibration falling="0.0" reference_position="0.0" rising="0.0"/>
    <dynamics damping="1.0"/>
    <limit effort="100.0" lower="-0.2617993877991494" upper="0.2617993877991494" velocity="1.0"/>
  </joint>
  <joint name="hips.004_joint" type="revolute">
    <origin rpy="-1.5707963705062866 -0 -1.5707963705062866" xyz="1.0521336236290475e-08 8.95091289524062e-09 3.8014136305023264e-08"/>
    <parent link="joint_1_obj_hips.004_link"/>
    <child link="hips.004_link"/>
    <axis xyz="1 0 0"/>
    <calibration falling="0.0" reference_position="0.0" rising="0.0"/>
    <dynamics damping="1.0"/>
    <limit effort="100.0" lower="-0.2617993877991494" upper="0.2617993877991494" velocity="1.0"/>
  </joint>
  <joint name="joint_1_obj_hips.005_joint" type="revolute">
    <origin rpy="1.5707963705062866 -1.570796251296997 0" xyz="-3.441739396603421e-12 -0.010583988091497076 7.339162084604722e-05"/>
    <parent link="hips.004_link"/>
    <child link="joint_1_obj_hips.005_link"/>
    <axis xyz="1 0 0"/>
    <calibration falling="0.0" reference_position="0.0" rising="0.0"/>
    <dynamics damping="1.0"/>
    <limit effort="100.0" lower="-0.2617993877991494" upper="0.2617993877991494" velocity="1.0"/>
  </joint>
  <joint name="hips.005_joint" type="revolute">
    <origin rpy="-1.5707963705062866 -0 -1.5707963705062866" xyz="1.5733018351403303e-08 -4.3121169945445983e-11 -1.1124223272292375e-07"/>
    <parent link="joint_1_obj_hips.005_link"/>
    <child link="hips.005_link"/>
    <axis xyz="1 0 0"/>
    <calibration falling="0.0" reference_position="0.0" rising="0.0"/>
    <dynamics damping="1.0"/>
    <limit effort="100.0" lower="-0.2617993877991494" upper="0.2617993877991494" velocity="1.0"/>
  </joint>
  <joint name="joint_1_obj_hips.006_joint" type="revolute">
    <origin rpy="1.5707963705062866 -1.570796251296997 0" xyz="8.908926948860932e-09 -0.013158990091224343 -0.0005119846864146821"/>
    <parent link="hips.005_link"/>
    <child link="joint_1_obj_hips.006_link"/>
    <axis xyz="1 0 0"/>
    <calibration falling="0.0" reference_position="0.0" rising="0.0"/>
    <dynamics damping="1.0"/>
    <limit effort="100.0" lower="-0.2617993877991494" upper="0.2617993877991494" velocity="1.0"/>
  </joint>
  <joint name="hips.006_joint" type="revolute">
    <origin rpy="-1.5707963705062866 -0 -1.5707963705062866" xyz="-1.4978748519903374e-09 8.933810175148273e-09 -1.5147996786316894e-07"/>
    <parent link="joint_1_obj_hips.006_link"/>
    <child link="hips.006_link"/>
    <axis xyz="1 0 0"/>
    <calibration falling="0.0" reference_position="0.0" rising="0.0"/>
    <dynamics damping="1.0"/>
    <limit effort="100.0" lower="-0.2617993877991494" upper="0.2617993877991494" velocity="1.0"/>
  </joint>
  <joint name="joint_1_obj_hips.007_joint" type="revolute">
    <origin rpy="1.5707963705062866 -1.570796251296997 0" xyz="1.7870269827226257e-08 -0.01147132246777316 -0.0001301024965253382"/>
    <parent link="hips.006_link"/>
    <child link="joint_1_obj_hips.007_link"/>
    <axis xyz="1 0 0"/>
    <calibration falling="0.0" reference_position="0.0" rising="0.0"/>
    <dynamics damping="1.0"/>
    <limit effort="100.0" lower="-0.2617993877991494" upper="0.2617993877991494" velocity="1.0"/>
  </joint>
  <joint name="hips.007_joint" type="revolute">
    <origin rpy="-1.5707963705062866 -0 -1.5707963705062866" xyz="4.668560881517795e-08 1.790546575596938e-08 -8.495713567334214e-08"/>
    <parent link="joint_1_obj_hips.007_link"/>
    <child link="hips.007_link"/>
    <axis xyz="1 0 0"/>
    <calibration falling="0.0" reference_position="0.0" rising="0.0"/>
    <dynamics damping="1.0"/>
    <limit effort="100.0" lower="-0.2617993877991494" upper="0.2617993877991494" velocity="1.0"/>
  </joint>
  <joint name="joint_1_obj_hips.008_joint" type="revolute">
    <origin rpy="1.5707963705062866 -1.570796251296997 0" xyz="-8.92630847708894e-09 -0.011710945623863989 -0.00013964258726757023"/>
    <parent link="hips.007_link"/>
    <child link="joint_1_obj_hips.008_link"/>
    <axis xyz="1 0 0"/>
    <calibration falling="0.0" reference_position="0.0" rising="0.0"/>
    <dynamics damping="1.0"/>
    <limit effort="100.0" lower="-0.2617993877991494" upper="0.2617993877991494" velocity="1.0"/>
  </joint>
  <joint name="hips.008_joint" type="revolute">
    <origin rpy="-1.5707963705062866 -0 -1.5707963705062866" xyz="-6.845514316002599e-09 -8.955722468854271e-09 5.3673020479413845e-08"/>
    <parent link="joint_1_obj_hips.008_link"/>
    <child link="hips.008_link"/>
    <axis xyz="1 0 0"/>
    <calibration falling="0.0" reference_position="0.0" rising="0.0"/>
    <dynamics damping="1.0"/>
    <limit effort="100.0" lower="-0.2617993877991494" upper="0.2617993877991494" velocity="1.0"/>
  </joint>
  <joint name="joint_1_obj_hips.009_joint" type="revolute">
    <origin rpy="1.5707963705062866 -1.570796251296997 0" xyz="-1.73938747671781e-11 -0.0110112159568021 -0.00010183736606312818"/>
    <parent link="hips.008_link"/>
    <child link="joint_1_obj_hips.009_link"/>
    <axis xyz="1 0 0"/>
    <calibration falling="0.0" reference_position="0.0" rising="0.0"/>
    <dynamics damping="1.0"/>
    <limit effort="100.0" lower="-0.2617993877991494" upper="0.2617993877991494" velocity="1.0"/>
  </joint>
  <joint name="hips.009_joint" type="revolute">
    <origin rpy="-1.5707963705062866 -0 -1.5707963705062866" xyz="2.5595102888683713e-08 4.2455924921047906e-12 -2.2906296419744843e-08"/>
    <parent link="joint_1_obj_hips.009_link"/>
    <child link="hips.009_link"/>
    <axis xyz="1 0 0"/>
    <calibration falling="0.0" reference_position="0.0" rising="0.0"/>
    <dynamics damping="1.0"/>
    <limit effort="100.0" lower="-0.2617993877991494" upper="0.2617993877991494" velocity="1.0"/>
  </joint>
  <joint name="joint_1_obj_hips.010_joint" type="revolute">
    <origin rpy="1.5707963705062866 -1.570796251296997 0" xyz="2.6831624966752423e-08 -0.012032318761492355 -5.1346305648281715e-05"/>
    <parent link="hips.009_link"/>
    <child link="joint_1_obj_hips.010_link"/>
    <axis xyz="1 0 0"/>
    <calibration falling="0.0" reference_position="0.0" rising="0.0"/>
    <dynamics damping="1.0"/>
    <limit effort="100.0" lower="-0.2617993877991494" upper="0.2617993877991494" velocity="1.0"/>
  </joint>
  <joint name="hips.010_joint" type="revolute">
    <origin rpy="-1.5707963705062866 -0 -1.5707963705062866" xyz="1.429832606087126e-08 2.681013488345454e-08 4.4734634225801863e-08"/>
    <parent link="joint_1_obj_hips.010_link"/>
    <child link="hips.010_link"/>
    <axis xyz="1 0 0"/>
    <calibration falling="0.0" reference_position="0.0" rising="0.0"/>
    <dynamics damping="1.0"/>
    <limit effort="100.0" lower="-0.2617993877991494" upper="0.2617993877991494" velocity="1.0"/>
  </joint>
  <joint name="joint_1_obj_hips.011_joint" type="revolute">
    <origin rpy="1.5707963705062866 -1.570796251296997 0" xyz="1.78703551222582e-08 -0.0095251814435926 -0.00048124131084646693"/>
    <parent link="hips.010_link"/>
    <child link="joint_1_obj_hips.011_link"/>
    <axis xyz="1 0 0"/>
    <calibration falling="0.0" reference_position="0.0" rising="0.0"/>
    <dynamics damping="1.0"/>
    <limit effort="100.0" lower="-0.2617993877991494" upper="0.2617993877991494" velocity="1.0"/>
  </joint>
  <joint name="hips.011_joint" type="revolute">
    <origin rpy="-1.5707963705062866 -0 -1.5707963705062866" xyz="3.228599703625091e-08 1.7897085519081042e-08 -1.02277750454289e-07"/>
    <parent link="joint_1_obj_hips.011_link"/>
    <child link="hips.011_link"/>
    <axis xyz="1 0 0"/>
    <calibration falling="0.0" reference_position="0.0" rising="0.0"/>
    <dynamics damping="1.0"/>
    <limit effort="100.0" lower="-0.2617993877991494" upper="0.2617993877991494" velocity="1.0"/>
  </joint>
  <joint name="joint_1_obj_hips.012_joint" type="revolute">
    <origin rpy="1.5707963705062866 -1.570796251296997 0" xyz="-8.920398597563233e-09 -0.01065604072281845 -0.00017535668981216723"/>
    <parent link="hips.011_link"/>
    <child link="joint_1_obj_hips.012_link"/>
    <axis xyz="1 0 0"/>
    <calibration falling="0.0" reference_position="0.0" rising="0.0"/>
    <dynamics damping="1.0"/>
    <limit effort="100.0" lower="-0.2617993877991494" upper="0.2617993877991494" velocity="1.0"/>
  </joint>
  <joint name="hips.012_joint" type="revolute">
    <origin rpy="-1.5707963705062866 -0 -1.5707963705062866" xyz="-6.2694945753498096e-09 -8.9316980569198e-09 7.048194183423516e-08"/>
    <parent link="joint_1_obj_hips.012_link"/>
    <child link="hips.012_link"/>
    <axis xyz="1 0 0"/>
    <calibration falling="0.0" reference_position="0.0" rising="0.0"/>
    <dynamics damping="1.0"/>
    <limit effort="100.0" lower="-0.2617993877991494" upper="0.2617993877991494" velocity="1.0"/>
  </joint>
  <joint name="joint_1_obj_hips.013_joint" type="revolute">
    <origin rpy="1.5707963705062866 -1.570796251296997 0" xyz="-8.926149615091948e-09 -0.009141241167830438 0.0002488100964687448"/>
    <parent link="hips.012_link"/>
    <child link="joint_1_obj_hips.013_link"/>
    <axis xyz="1 0 0"/>
    <calibration falling="0.0" reference_position="0.0" rising="0.0"/>
    <dynamics damping="1.0"/>
    <limit effort="100.0" lower="-0.2617993877991494" upper="0.2617993877991494" velocity="1.0"/>
  </joint>
  <joint name="hips.013_joint" type="revolute">
    <origin rpy="-1.5707963705062866 -0 -1.5707963705062866" xyz="8.640530671129688e-09 -8.901620363187168e-09 6.654900497037832e-08"/>
    <parent link="joint_1_obj_hips.013_link"/>
    <child link="hips.013_link"/>
    <axis xyz="1 0 0"/>
    <calibration falling="0.0" reference_position="0.0" rising="0.0"/>
    <dynamics damping="1.0"/>
    <limit effort="100.0" lower="-0.2617993877991494" upper="0.2617993877991494" velocity="1.0"/>
  </joint>
  <joint name="joint_1_obj_hips.014_joint" type="revolute">
    <origin rpy="1.5707963705062866 -1.570796251296997 0" xyz="1.7917362280549545e-08 -0.008613624933377917 -0.0006310991695901436"/>
    <parent link="hips.013_link"/>
    <child link="joint_1_obj_hips.014_link"/>
    <axis xyz="1 0 0"/>
    <calibration falling="0.0" reference_position="0.0" rising="0.0"/>
    <dynamics damping="1.0"/>
    <limit effort="100.0" lower="-0.2617993877991494" upper="0.2617993877991494" velocity="1.0"/>
  </joint>
  <joint name="hips.014_joint" type="revolute">
    <origin rpy="-1.5707963705062866 -0 -1.5707963705062866" xyz="-1.1237652444045792e-08 1.7895479840104727e-08 1.6799277898509908e-07"/>
    <parent link="joint_1_obj_hips.014_link"/>
    <child link="hips.014_link"/>
    <axis xyz="1 0 0"/>
    <calibration falling="0.0" reference_position="0.0" rising="0.0"/>
    <dynamics damping="1.0"/>
    <limit effort="100.0" lower="-0.2617993877991494" upper="0.2617993877991494" velocity="1.0"/>
  </joint>
  <joint name="joint_1_obj_hips.015_joint" type="revolute">
    <origin rpy="1.5707963705062866 -1.570796251296997 0" xyz="1.7893364523312556e-08 -0.008035068542835422 0.00014383829274104004"/>
    <parent link="hips.014_link"/>
    <child link="joint_1_obj_hips.015_link"/>
    <axis xyz="1 0 0"/>
    <calibration falling="0.0" reference_position="0.0" rising="0.0"/>
    <dynamics damping="1.0"/>
    <limit effort="100.0" lower="-0.2617993877991494" upper="0.2617993877991494" velocity="1.0"/>
  </joint>
  <joint name="hips.015_joint" type="revolute">
    <origin rpy="-1.5707963705062866 -0 -1.5707963705062866" xyz="-1.423107306056049e-08 1.7883132318043168e-08 -4.941862796392415e-08"/>
    <parent link="joint_1_obj_hips.015_link"/>
    <child link="hips.015_link"/>
    <axis xyz="1 0 0"/>
    <calibration falling="0.0" reference_position="0.0" rising="0.0"/>
    <dynamics damping="1.0"/>
    <limit effort="100.0" lower="-0.2617993877991494" upper="0.2617993877991494" velocity="1.0"/>
  </joint>
  <joint name="joint_1_obj_hips.016_joint" type="revolute">
    <origin rpy="1.5707963705062866 -1.570796251296997 0" xyz="2.6826545647600254e-08 -0.01030501207310408 -0.00023898770728402602"/>
    <parent link="hips.015_link"/>
    <child link="joint_1_obj_hips.016_link"/>
    <axis xyz="1 0 0"/>
    <calibration falling="0.0" reference_position="0.0" rising="0.0"/>
    <dynamics damping="1.0"/>
    <limit effort="100.0" lower="-0.2617993877991494" upper="0.2617993877991494" velocity="1.0"/>
  </joint>
  <joint name="hips.016_joint" type="revolute">
    <origin rpy="-1.5707963705062866 -0 -1.5707963705062866" xyz="5.950164369294172e-09 2.6863373910017176e-08 2.0709198750947416e-08"/>
    <parent link="joint_1_obj_hips.016_link"/>
    <child link="hips.016_link"/>
    <axis xyz="1 0 0"/>
    <calibration falling="0.0" reference_position="0.0" rising="0.0"/>
    <dynamics damping="1.0"/>
    <limit effort="100.0" lower="-0.2617993877991494" upper="0.2617993877991494" velocity="1.0"/>
  </joint>
  <joint name="joint_1_obj_hips.017_joint" type="revolute">
    <origin rpy="1.5707963705062866 -1.570796251296997 0" xyz="-1.7857511822823475e-08 -0.010555223608708086 4.403686695805299e-05"/>
    <parent link="hips.016_link"/>
    <child link="joint_1_obj_hips.017_link"/>
    <axis xyz="1 0 0"/>
    <calibration falling="0.0" reference_position="0.0" rising="0.0"/>
    <dynamics damping="1.0"/>
    <limit effort="100.0" lower="-0.2617993877991494" upper="0.2617993877991494" velocity="1.0"/>
  </joint>
  <joint name="hips.017_joint" type="revolute">
    <origin rpy="-1.5707963705062866 -0 -1.5707963705062866" xyz="-3.0960161464047433e-09 -1.7855621471678052e-08 1.241167757278484e-07"/>
    <parent link="joint_1_obj_hips.017_link"/>
    <child link="hips.017_link"/>
    <axis xyz="1 0 0"/>
    <calibration falling="0.0" reference_position="0.0" rising="0.0"/>
    <dynamics damping="1.0"/>
    <limit effort="100.0" lower="-0.2617993877991494" upper="0.2617993877991494" velocity="1.0"/>
  </joint>
  <joint name="joint_1_obj_hips.018_joint" type="revolute">
    <origin rpy="1.5707963705062866 -1.570796251296997 0" xyz="1.7992743897404424e-08 -0.012374542208266615 -0.00031585405939997535"/>
    <parent link="hips.017_link"/>
    <child link="joint_1_obj_hips.018_link"/>
    <axis xyz="1 0 0"/>
    <calibration falling="0.0" reference_position="0.0" rising="0.0"/>
    <dynamics damping="1.0"/>
    <limit effort="100.0" lower="-0.2617993877991494" upper="0.2617993877991494" velocity="1.0"/>
  </joint>
  <joint name="hips.018_joint" type="revolute">
    <origin rpy="-1.5707963705062866 -0 -1.5707963705062866" xyz="1.0296475075956572e-08 1.7850469651748732e-08 -2.5658231874200068e-08"/>
    <parent link="joint_1_obj_hips.018_link"/>
    <child link="hips.018_link"/>
    <axis xyz="1 0 0"/>
    <calibration falling="0.0" reference_position="0.0" rising="0.0"/>
    <dynamics damping="1.0"/>
    <limit effort="100.0" lower="-0.2617993877991494" upper="0.2617993877991494" velocity="1.0"/>
  </joint>
  <joint name="joint_1_obj_hips.019_joint" type="revolute">
    <origin rpy="1.5707963705062866 -1.570796251296997 0" xyz="8.913898583035274e-09 -0.011255027062386791 -0.0001398434217215333"/>
    <parent link="hips.018_link"/>
    <child link="joint_1_obj_hips.019_link"/>
    <axis xyz="1 0 0"/>
    <calibration falling="0.0" reference_position="0.0" rising="0.0"/>
    <dynamics damping="1.0"/>
    <limit effort="100.0" lower="-0.2617993877991494" upper="0.2617993877991494" velocity="1.0"/>
  </joint>
  <joint name="hips.019_joint" type="revolute">
    <origin rpy="-1.5707963705062866 -0 -1.5707963705062866" xyz="-2.0326319214796132e-09 8.947202561351126e-09 4.250774726709856e-08"/>
    <parent link="joint_1_obj_hips.019_link"/>
    <child link="hips.019_link"/>
    <axis xyz="1 0 0"/>
    <calibration falling="0.0" reference_position="0.0" rising="0.0"/>
    <dynamics damping="1.0"/>
    <limit effort="100.0" lower="-0.2617993877991494" upper="0.2617993877991494" velocity="1.0"/>
  </joint>
  <joint name="joint_1_obj_hips.020_joint" type="revolute">
    <origin rpy="1.5707963705062866 -1.570796251296997 0" xyz="8.869610203887091e-09 -0.01140653446427109 -0.00016824291928993484"/>
    <parent link="hips.019_link"/>
    <child link="joint_1_obj_hips.020_link"/>
    <axis xyz="1 0 0"/>
    <calibration falling="0.0" reference_position="0.0" rising="0.0"/>
    <dynamics damping="1.0"/>
    <limit effort="100.0" lower="-0.2617993877991494" upper="0.2617993877991494" velocity="1.0"/>
  </joint>
  <joint name="hips.020_joint" type="revolute">
    <origin rpy="-1.5707963705062866 -0 -1.5707963705062866" xyz="2.9383245038690964e-08 8.943523146910712e-09 3.3811902234660288e-09"/>
    <parent link="joint_1_obj_hips.020_link"/>
    <child link="hips.020_link"/>
    <axis xyz="1 0 0"/>
    <calibration falling="0.0" reference_position="0.0" rising="0.0"/>
    <dynamics damping="1.0"/>
    <limit effort="100.0" lower="-0.2617993877991494" upper="0.2617993877991494" velocity="1.0"/>
  </joint>
  <joint name="joint_1_obj_hips.021_joint" type="revolute">
    <origin rpy="1.5707963705062866 -1.570796251296997 0" xyz="2.5995598916303707e-13 -0.013215442442984227 0.0008021713444686385"/>
    <parent link="hips.020_link"/>
    <child link="joint_1_obj_hips.021_link"/>
    <axis xyz="1 0 0"/>
    <calibration falling="0.0" reference_position="0.0" rising="0.0"/>
    <dynamics damping="1.0"/>
    <limit effort="100.0" lower="-0.2617993877991494" upper="0.2617993877991494" velocity="1.0"/>
  </joint>
  <joint name="hips.021_joint" type="revolute">
    <origin rpy="-1.5707963705062866 -0 -1.5707963705062866" xyz="-1.1257369456867173e-08 -2.0953426364853254e-11 -2.007046690424689e-08"/>
    <parent link="joint_1_obj_hips.021_link"/>
    <child link="hips.021_link"/>
    <axis xyz="1 0 0"/>
    <calibration falling="0.0" reference_position="0.0" rising="0.0"/>
    <dynamics damping="1.0"/>
    <limit effort="100.0" lower="-0.2617993877991494" upper="0.2617993877991494" velocity="1.0"/>
  </joint>
  <joint name="hips_joint" type="revolute">
    <origin rpy="0 -0 0" xyz="-1.0918102478339009e-11 -0.022753831690986992 0.016793550020772763"/>
    <parent link="hips.021_link"/>
    <child link="hips_link"/>
    <axis xyz="1 0 0"/>
    <calibration falling="0.0" reference_position="0.0" rising="0.0"/>
    <dynamics damping="1.0"/>
    <limit effort="100.0" lower="-0.5235987755982988" upper="0.5235987755982988" velocity="1.0"/>
  </joint>
  <joint name="spine_joint" type="revolute">
    <origin rpy="0 -0 0" xyz="-3.4491626257322444e-11 -0.01858155849926213 0.022784424069510756"/>
    <parent link="hips_link"/>
    <child link="spine_link"/>
    <axis xyz="1 0 0"/>
    <calibration falling="0.0" reference_position="0.0" rising="0.0"/>
    <dynamics damping="1.0"/>
    <limit effort="100.0" lower="0.0" upper="0.0" velocity="1.0"/>
  </joint>
  <joint name="chest_joint" type="revolute">
    <origin rpy="0 -0 0" xyz="0 -0.05767780436388925 0.003555576107657221"/>
    <parent link="spine_link"/>
    <child link="chest_link"/>
    <axis xyz="1 0 0"/>
    <calibration falling="0.0" reference_position="0.0" rising="0.0"/>
    <dynamics damping="1.0"/>
    <limit effort="100.0" lower="0.0" upper="0.0" velocity="1.0"/>
  </joint>
  <joint name="neck_joint" type="revolute">
    <origin rpy="0 -0 0" xyz="0 -0.06541673255608949 -0.0033672307373272536"/>
    <parent link="chest_link"/>
    <child link="neck_link"/>
    <axis xyz="1 0 0"/>
    <calibration falling="0.0" reference_position="0.0" rising="0.0"/>
    <dynamics damping="1.0"/>
    <limit effort="100.0" lower="0.0" upper="0.0" velocity="1.0"/>
  </joint>
  <joint name="head_joint" type="revolute">
    <origin rpy="0 -0 0" xyz="-1.4265389757035994e-12 -0.03748049783299123 -0.013961685628116616"/>
    <parent link="neck_link"/>
    <child link="head_link"/>
    <axis xyz="1 0 0"/>
    <calibration falling="0.0" reference_position="0.0" rising="0.0"/>
    <dynamics damping="1.0"/>
    <limit effort="100.0" lower="0.0" upper="0.0" velocity="1.0"/>
  </joint>
  <joint name="nose_joint" type="revolute">
    <origin rpy="0 -0 0" xyz="2.6434096541958984e-11 -0.035097181165983926 0.002804151369156793"/>
    <parent link="head_link"/>
    <child link="nose_link"/>
    <axis xyz="1 0 0"/>
    <calibration falling="0.0" reference_position="0.0" rising="0.0"/>
    <dynamics damping="1.0"/>
    <limit effort="100.0" lower="0.0" upper="0.0" velocity="1.0"/>
  </joint>
  <joint name="mouth_joint" type="revolute">
    <origin rpy="0 -0 0" xyz="3.96582567235303e-12 -0.03748050006894932 -0.013961699043865128"/>
    <parent link="neck_link"/>
    <child link="mouth_link"/>
    <axis xyz="1 0 0"/>
    <calibration falling="0.0" reference_position="0.0" rising="0.0"/>
    <dynamics damping="1.0"/>
    <limit effort="100.0" lower="0.0" upper="0.0" velocity="1.0"/>
  </joint>
  <joint name="neck.001_joint" type="revolute">
    <origin rpy="0 -0 0" xyz="4.1172761537069976e-13 -0.03748049336107506 -0.013961688982053744"/>
    <parent link="neck_link"/>
    <child link="neck.001_link"/>
    <axis xyz="1 0 0"/>
    <calibration falling="0.0" reference_position="0.0" rising="0.0"/>
    <dynamics damping="1.0"/>
    <limit effort="100.0" lower="0.0" upper="0.0" velocity="1.0"/>
  </joint>
  <joint name="neck.002_joint" type="revolute">
    <origin rpy="0 -0 0" xyz="4.3819073221454227e-13 -0.03748049336107506 -0.013961688982053744"/>
    <parent link="neck_link"/>
    <child link="neck.002_link"/>
    <axis xyz="1 0 0"/>
    <calibration falling="0.0" reference_position="0.0" rising="0.0"/>
    <dynamics damping="1.0"/>
    <limit effort="100.0" lower="0.0" upper="0.0" velocity="1.0"/>
  </joint>
  <joint name="shoulder.L_joint" type="revolute">
    <origin rpy="0 -0 0" xyz="1.1181119163421356e-09 -0.06541673255608949 -0.0033672673511409013"/>
    <parent link="chest_link"/>
    <child link="shoulder.L_link"/>
    <axis xyz="1 0 0"/>
    <calibration falling="0.0" reference_position="0.0" rising="0.0"/>
    <dynamics damping="1.0"/>
    <limit effort="100.0" lower="0.0" upper="0.0" velocity="1.0"/>
  </joint>
  <joint name="upper_arm.L_joint" type="revolute">
    <origin rpy="0 -0.19198621809482574 0" xyz="0.022067911301060228 -0.010050855189458474 -0.010896033929972404"/>
    <parent link="shoulder.L_link"/>
    <child link="upper_arm.L_link"/>
    <axis xyz="1 0 0"/>
    <calibration falling="0.0" reference_position="0.0" rising="0.0"/>
    <dynamics damping="1.0"/>
    <limit effort="100.0" lower="-0.6108652381980153" upper="0.5235987755982988" velocity="1.0"/>
  </joint>
  <joint name="forearm.L_joint" type="revolute">
    <origin rpy="0 -0 0" xyz="0.0014567613499560927 0.043208320356820096 -0.0245942622067874"/>
    <parent link="upper_arm.L_link"/>
    <child link="forearm.L_link"/>
    <axis xyz="1 0 0"/>
    <calibration falling="0.0" reference_position="0.0" rising="0.0"/>
    <dynamics damping="1.0"/>
    <limit effort="100.0" lower="-0.5235987755982988" upper="1.3962634015954636" velocity="1.0"/>
  </joint>
  <joint name="wrist.L_joint" type="revolute">
    <origin rpy="0 0.19198621809482574 0" xyz="0.0019657679847590037 -0.04566185952345592 -0.021615963801142613"/>
    <parent link="forearm.L_link"/>
    <child link="wrist.L_link"/>
    <axis xyz="1 0 0"/>
    <calibration falling="0.0" reference_position="0.0" rising="0.0"/>
    <dynamics damping="1.0"/>
    <limit effort="100.0" lower="-0.6108652381980153" upper="1.5707963267948966" velocity="1.0"/>
  </joint>
  <joint name="shoulder.R_joint" type="revolute">
    <origin rpy="0 -0 0" xyz="1.118146833995837e-09 -0.06541673255608949 -0.003367213688146853"/>
    <parent link="chest_link"/>
    <child link="shoulder.R_link"/>
    <axis xyz="1 0 0"/>
    <calibration falling="0.0" reference_position="0.0" rising="0.0"/>
    <dynamics damping="1.0"/>
    <limit effort="100.0" lower="0.0" upper="0.0" velocity="1.0"/>
  </joint>
  <joint name="upper_arm.R_joint" type="revolute">
    <origin rpy="0 0.19198621809482574 0" xyz="-0.0220679157729764 -0.010050835065835706 -0.01089609094690358"/>
    <parent link="shoulder.R_link"/>
    <child link="upper_arm.R_link"/>
    <axis xyz="1 0 0"/>
    <calibration falling="0.0" reference_position="0.0" rising="0.0"/>
    <dynamics damping="1.0"/>
    <limit effort="100.0" lower="-0.6108652381980153" upper="0.5235987755982988" velocity="1.0"/>
  </joint>
  <joint name="forearm.R_joint" type="revolute">
    <origin rpy="0 -0 0" xyz="-0.0014567756041888869 0.04320829799723924 -0.024594221959541862"/>
    <parent link="upper_arm.R_link"/>
    <child link="forearm.R_link"/>
    <axis xyz="1 0 0"/>
    <calibration falling="0.0" reference_position="0.0" rising="0.0"/>
    <dynamics damping="1.0"/>
    <limit effort="100.0" lower="-0.5235987755982988" upper="1.3962634015954636" velocity="1.0"/>
  </joint>
  <joint name="wrist.R_joint" type="revolute">
    <origin rpy="0 -0.19198621809482574 0" xyz="-0.001965777208086106 -0.0456618774111206 -0.02161601299222049"/>
    <parent link="forearm.R_link"/>
    <child link="wrist.R_link"/>
    <axis xyz="1 0 0"/>
    <calibration falling="0.0" reference_position="0.0" rising="0.0"/>
    <dynamics damping="1.0"/>
    <limit effort="100.0" lower="-0.6108652381980153" upper="1.5707963267948966" velocity="1.0"/>
  </joint>
  <joint name="spine.001_joint" type="revolute">
    <origin rpy="0 -0 0" xyz="-5.7047670141226105e-06 -0.09178576636950098 -0.04398121504435082"/>
    <parent link="spine_link"/>
    <child link="spine.001_link"/>
    <axis xyz="1 0 0"/>
    <calibration falling="0.0" reference_position="0.0" rising="0.0"/>
    <dynamics damping="1.0"/>
    <limit effort="100.0" lower="0.0" upper="0.0" velocity="1.0"/>
  </joint>
  <joint name="thigh.L_joint" type="revolute">
    <origin rpy="0 -0 0" xyz="0.027385589797335186 -0.022952268499145667 0.015287970997939215"/>
    <parent link="hips_link"/>
    <child link="thigh.L_link"/>
    <axis xyz="1 0 0"/>
    <calibration falling="0.0" reference_position="0.0" rising="0.0"/>
    <dynamics damping="1.0"/>
    <limit effort="100.0" lower="-0.5235987755982988" upper="0.5235987755982988" velocity="1.0"/>
  </joint>
  <joint name="shin.L_joint" type="revolute">
    <origin rpy="0 -0 0" xyz="0.003490970893728629 -0.0438696765112212 -0.014771866034699599"/>
    <parent link="thigh.L_link"/>
    <child link="shin.L_link"/>
    <axis xyz="1 0 0"/>
    <calibration falling="0.0" reference_position="0.0" rising="0.0"/>
    <dynamics damping="1.0"/>
    <limit effort="100.0" lower="-0.3490658503988659" upper="1.5707963267948966" velocity="1.0"/>
  </joint>
  <joint name="shin_lower.L_joint" type="revolute">
    <origin rpy="0 -0 0" xyz="0.0013861989846986056 0.03997179338785628 -0.03266355320609815"/>
    <parent link="shin.L_link"/>
    <child link="shin_lower.L_link"/>
    <axis xyz="1 0 0"/>
    <calibration falling="0.0" reference_position="0.0" rising="0.0"/>
    <dynamics damping="1.0"/>
    <limit effort="100.0" lower="-0.5235987755982988" upper="2.0943951023931953" velocity="1.0"/>
  </joint>
  <joint name="thigh.R_joint" type="revolute">
    <origin rpy="0 -0 0" xyz="-0.02757728071995036 -0.022952268499145667 0.015287988885603898"/>
    <parent link="hips_link"/>
    <child link="thigh.R_link"/>
    <axis xyz="1 0 0"/>
    <calibration falling="0.0" reference_position="0.0" rising="0.0"/>
    <dynamics damping="1.0"/>
    <limit effort="100.0" lower="-0.5235987755982988" upper="0.5235987755982988" velocity="1.0"/>
  </joint>
  <joint name="shin.R_joint" type="revolute">
    <origin rpy="0 -0 0" xyz="-0.0035640973439204915 -0.043869707814634396 -0.014771834731286404"/>
    <parent link="thigh.R_link"/>
    <child link="shin.R_link"/>
    <axis xyz="1 0 0"/>
    <calibration falling="0.0" reference_position="0.0" rising="0.0"/>
    <dynamics damping="1.0"/>
    <limit effort="100.0" lower="-0.3490658503988659" upper="1.5707963267948966" velocity="1.0"/>
  </joint>
  <joint name="shin_lower.R_joint" type="revolute">
    <origin rpy="0 -0 0" xyz="-0.0016238500257581556 0.03997186493851501 -0.032663613576966455"/>
    <parent link="shin.R_link"/>
    <child link="shin_lower.R_link"/>
    <axis xyz="1 0 0"/>
    <calibration falling="0.0" reference_position="0.0" rising="0.0"/>
    <dynamics damping="1.0"/>
    <limit effort="100.0" lower="-0.5235987755982988" upper="2.0943951023931953" velocity="1.0"/>
  </joint>
  <link name="root_link">
    <inertial>
      <mass value="1" />
      <inertia ixx="0" iyy="0" izz="0" ixy="0" ixz="0" iyz="0" />
    </inertial>
  </link>
  <link name="hips.001_link">
    <inertial>
      <mass value="1" />
      <inertia ixx="0" iyy="0" izz="0" ixy="0" ixz="0" iyz="0" />
    </inertial>
  </link>
  <link name="joint_1_obj_hips.002_link">
    <inertial>
      <mass value="1" />
      <inertia ixx="0" iyy="0" izz="0" ixy="0" ixz="0" iyz="0" />
    </inertial>
    <visual>
      <origin rpy="-1.570796251296997 1.2986136341272352e-15 -1.5707963705062866" xyz="-4.127928130479681e-08 -2.540354997141726e-09 2.861648492256976e-07"/>
      <geometry>
        <mesh filename="file://meshes/COL_joint_1_obj_hips.002_convex_hull.dae" scale="0.15005260705947876 0.15005260705947876 0.15005260705947876"/>
      </geometry>
    </visual>
    <visual>
      <origin rpy="-1.570796251296997 1.2986136341272352e-15 -1.5707963705062866" xyz="-4.127928130479681e-08 -2.540354997141726e-09 2.861648492256976e-07"/>
      <geometry>
        <mesh filename="file://meshes/joint_1_obj_hips.002.dae" scale="0.15005260705947876 0.15005260705947876 0.15005260705947876"/>
      </geometry>
    </visual>
  </link>
  <link name="hips.002_link">
    <inertial>
      <mass value="1" />
      <inertia ixx="0" iyy="0" izz="0" ixy="0" ixz="0" iyz="0" />
    </inertial>
    <visual>
      <origin rpy="9.045468374324628e-08 4.365573147424584e-08 1.1658220978763394e-14" xyz="-0.0001616733250667246 -0.007651094727701979 -0.000259805507695568"/>
      <geometry>
        <mesh filename="file://meshes/obj_hips.002.dae" scale="0.15005260705947876 0.15005260705947876 0.15005260705947876"/>
      </geometry>
    </visual>
    <collision>
      <origin rpy="9.045468374324628e-08 4.365573147424584e-08 1.1658220978763394e-14" xyz="-0.0001616733250667246 -0.007651094727701979 -0.000259805507695568"/>
      <geometry>
        <mesh filename="file://collisions/COL_obj_hips.002_convex_hull.dae" scale="0.15005260705947876 0.15005260705947876 0.15005260705947876"/>
      </geometry>
    </collision>
  </link>
  <link name="joint_1_obj_hips.003_link">
    <inertial>
      <mass value="1" />
      <inertia ixx="0" iyy="0" izz="0" ixy="0" ixz="0" iyz="0" />
    </inertial>
    <visual>
      <origin rpy="-1.570796251296997 -1.192092469182171e-07 -1.5707963705062866" xyz="-9.793441654424139e-08 -2.3379180606336602e-08 3.2593787144341113e-07"/>
      <geometry>
        <mesh filename="file://meshes/COL_joint_1_obj_hips.003_convex_hull.dae" scale="0.15005260705947876 0.15005260705947876 0.15005260705947876"/>
      </geometry>
    </visual>
    <visual>
      <origin rpy="-1.570796251296997 -1.192092469182171e-07 -1.5707963705062866" xyz="-9.793441654424139e-08 -2.3379180606336602e-08 3.2593787144341113e-07"/>
      <geometry>
        <mesh filename="file://meshes/joint_1_obj_hips.003.dae" scale="0.15005260705947876 0.15005260705947876 0.15005260705947876"/>
      </geometry>
    </visual>
  </link>
  <link name="hips.003_link">
    <inertial>
      <mass value="1" />
      <inertia ixx="0" iyy="0" izz="0" ixy="0" ixz="0" iyz="0" />
    </inertial>
    <visual>
      <origin rpy="1.958105144694855e-07 8.731148426477375e-08 -5.9604612800967516e-08" xyz="-0.00015319974266014835 -0.008712986997764238 -0.00020798965958357396"/>
      <geometry>
        <mesh filename="file://meshes/obj_hips.003.dae" scale="0.15005260705947876 0.15005260705947876 0.15005260705947876"/>
      </geometry>
    </visual>
    <collision>
      <origin rpy="1.958105144694855e-07 8.731148426477375e-08 -5.9604612800967516e-08" xyz="-0.00015319974266014835 -0.008712986997764238 -0.00020798965958357396"/>
      <geometry>
        <mesh filename="file://collisions/COL_obj_hips.003_convex_hull.dae" scale="0.15005260705947876 0.15005260705947876 0.15005260705947876"/>
      </geometry>
    </collision>
  </link>
  <link name="joint_1_obj_hips.004_link">
    <inertial>
      <mass value="1" />
      <inertia ixx="0" iyy="0" izz="0" ixy="0" ixz="0" iyz="0" />
    </inertial>
    <visual>
      <origin rpy="-1.5707961320877075 -5.9604552404834976e-08 -1.5707963705062866" xyz="-8.48654179254945e-08 1.0147447596146842e-08 6.924077373577655e-07"/>
      <geometry>
        <mesh filename="file://meshes/COL_joint_1_obj_hips.004_convex_hull.dae" scale="0.15005260705947876 0.15005260705947876 0.15005260705947876"/>
      </geometry>
    </visual>
    <visual>
      <origin rpy="-1.5707961320877075 -5.9604552404834976e-08 -1.5707963705062866" xyz="-8.48654179254945e-08 1.0147447596146842e-08 6.924077373577655e-07"/>
      <geometry>
        <mesh filename="file://meshes/joint_1_obj_hips.004.dae" scale="0.15005260705947876 0.15005260705947876 0.15005260705947876"/>
      </geometry>
    </visual>
  </link>
  <link name="hips.004_link">
    <inertial>
      <mass value="1" />
      <inertia ixx="0" iyy="0" izz="0" ixy="0" ixz="0" iyz="0" />
    </inertial>
    <visual>
      <origin rpy="2.8620706871151924e-07 1.3108359553370974e-07 5.959746118833209e-08" xyz="-0.0001574319047314629 -0.007031013800566921 -0.00011446107882876269"/>
      <geometry>
        <mesh filename="file://meshes/obj_hips.004.dae" scale="0.15005260705947876 0.15005260705947876 0.15005260705947876"/>
      </geometry>
    </visual>
    <collision>
      <origin rpy="2.8620706871151924e-07 1.3108359553370974e-07 5.959746118833209e-08" xyz="-0.0001574319047314629 -0.007031013800566921 -0.00011446107882876269"/>
      <geometry>
        <mesh filename="file://collisions/COL_obj_hips.004_convex_hull.dae" scale="0.15005260705947876 0.15005260705947876 0.15005260705947876"/>
      </geometry>
    </collision>
  </link>
  <link name="joint_1_obj_hips.005_link">
    <inertial>
      <mass value="1" />
      <inertia ixx="0" iyy="0" izz="0" ixy="0" ixz="0" iyz="0" />
    </inertial>
    <visual>
      <origin rpy="-1.570796251296997 -5.9604552404834976e-08 -1.5707964897155762" xyz="-4.829751859357668e-08 3.334113709651835e-08 1.223691248767656e-06"/>
      <geometry>
        <mesh filename="file://meshes/COL_joint_1_obj_hips.005_convex_hull.dae" scale="0.15005260705947876 0.15005259811564642 0.15005264283480813"/>
      </geometry>
    </visual>
    <visual>
      <origin rpy="-1.570796251296997 -5.9604552404834976e-08 -1.5707964897155762" xyz="-4.829751859357668e-08 3.334113709651835e-08 1.223691248767656e-06"/>
      <geometry>
        <mesh filename="file://meshes/joint_1_obj_hips.005.dae" scale="0.15005260705947876 0.15005259811564642 0.15005264283480813"/>
      </geometry>
    </visual>
  </link>
  <link name="hips.005_link">
    <inertial>
      <mass value="1" />
      <inertia ixx="0" iyy="0" izz="0" ixy="0" ixz="0" iyz="0" />
    </inertial>
    <visual>
      <origin rpy="2.4249305852208636e-07 1.7479750624715962e-07 -5.960454174669394e-08" xyz="-0.00015744773112228577 -0.007381856865760206 -0.0001769604307488848"/>
      <geometry>
        <mesh filename="file://meshes/obj_hips.005.dae" scale="0.15005260705947876 0.15005260705947876 0.15005264283480813"/>
      </geometry>
    </visual>
    <collision>
      <origin rpy="2.4249305852208636e-07 1.7479750624715962e-07 -5.960454174669394e-08" xyz="-0.00015744773112228577 -0.007381856865760206 -0.0001769604307488848"/>
      <geometry>
        <mesh filename="file://collisions/COL_obj_hips.005_convex_hull.dae" scale="0.15005260705947876 0.15005260705947876 0.15005264283480813"/>
      </geometry>
    </collision>
  </link>
  <link name="joint_1_obj_hips.006_link">
    <inertial>
      <mass value="1" />
      <inertia ixx="0" iyy="0" izz="0" ixy="0" ixz="0" iyz="0" />
    </inertial>
    <visual>
      <origin rpy="-1.5707961320877075 -1.788137637959153e-07 -1.5707964897155762" xyz="-3.738873607181533e-08 3.714492875251123e-08 1.549808273896159e-06"/>
      <geometry>
        <mesh filename="file://meshes/COL_joint_1_obj_hips.006_convex_hull.dae" scale="0.15005260705947876 0.15005260705947876 0.15005264283480813"/>
      </geometry>
    </visual>
    <visual>
      <origin rpy="-1.5707961320877075 -1.788137637959153e-07 -1.5707964897155762" xyz="-3.738873607181533e-08 3.714492875251123e-08 1.549808273896159e-06"/>
      <geometry>
        <mesh filename="file://meshes/joint_1_obj_hips.006.dae" scale="0.15005260705947876 0.15005260705947876 0.15005264283480813"/>
      </geometry>
    </visual>
  </link>
  <link name="hips.006_link">
    <inertial>
      <mass value="1" />
      <inertia ixx="0" iyy="0" izz="0" ixy="0" ixz="0" iyz="0" />
    </inertial>
    <visual>
      <origin rpy="3.6985142060075304e-07 2.1880248368688626e-07 -1.7881373537420586e-07" xyz="-0.0001574652519500952 -0.006624318738359669 -1.9682534181208848e-05"/>
      <geometry>
        <mesh filename="file://meshes/obj_hips.006.dae" scale="0.15005260705947876 0.15005258917181408 0.15005264283480813"/>
      </geometry>
    </visual>
    <collision>
      <origin rpy="3.6985142060075304e-07 2.1880248368688626e-07 -1.7881373537420586e-07" xyz="-0.0001574652519500952 -0.006624318738359669 -1.9682534181208848e-05"/>
      <geometry>
        <mesh filename="file://collisions/COL_obj_hips.006_convex_hull.dae" scale="0.15005260705947876 0.15005258917181408 0.15005264283480813"/>
      </geometry>
    </collision>
  </link>
  <link name="joint_1_obj_hips.007_link">
    <inertial>
      <mass value="1" />
      <inertia ixx="0" iyy="0" izz="0" ixy="0" ixz="0" iyz="0" />
    </inertial>
    <visual>
      <origin rpy="-1.5707961320877075 -1.7881370695249643e-07 -1.5707966089248657" xyz="-1.0074820582348543e-07 7.201792197519878e-08 7.30931272652555e-07"/>
      <geometry>
        <mesh filename="file://meshes/COL_joint_1_obj_hips.007_convex_hull.dae" scale="0.15005260705947876 0.15005258917181408 0.15005260705947876"/>
      </geometry>
    </visual>
    <visual>
      <origin rpy="-1.5707961320877075 -1.7881370695249643e-07 -1.5707966089248657" xyz="-1.0074820582348543e-07 7.201792197519878e-08 7.30931272652555e-07"/>
      <geometry>
        <mesh filename="file://meshes/joint_1_obj_hips.007.dae" scale="0.15005260705947876 0.15005258917181408 0.15005260705947876"/>
      </geometry>
    </visual>
  </link>
  <link name="hips.007_link">
    <inertial>
      <mass value="1" />
      <inertia ixx="0" iyy="0" izz="0" ixy="0" ixz="0" iyz="0" />
    </inertial>
    <visual>
      <origin rpy="4.378962330520153e-07 1.4330707642784546e-07 -1.7881379221762472e-07" xyz="-0.00015748722722565278 -0.008385935644578124 6.797303845253871e-05"/>
      <geometry>
        <mesh filename="file://meshes/obj_hips.007.dae" scale="0.15005260705947876 0.15005260705947876 0.15005264283480813"/>
      </geometry>
    </visual>
    <collision>
      <origin rpy="4.378962330520153e-07 1.4330707642784546e-07 -1.7881379221762472e-07" xyz="-0.00015748722722565278 -0.008385935644578124 6.797303845253871e-05"/>
      <geometry>
        <mesh filename="file://collisions/COL_obj_hips.007_convex_hull.dae" scale="0.15005260705947876 0.15005260705947876 0.15005264283480813"/>
      </geometry>
    </collision>
  </link>
  <link name="joint_1_obj_hips.008_link">
    <inertial>
      <mass value="1" />
      <inertia ixx="0" iyy="0" izz="0" ixy="0" ixz="0" iyz="0" />
    </inertial>
    <visual>
      <origin rpy="-1.570796012878418 -1.7881366431993229e-07 -1.5707964897155762" xyz="-2.3125515313715757e-08 1.0692866677902403e-07 1.0568467285615717e-06"/>
      <geometry>
        <mesh filename="file://meshes/COL_joint_1_obj_hips.008_convex_hull.dae" scale="0.15005260705947876 0.15005260705947876 0.15005264283480813"/>
      </geometry>
    </visual>
    <visual>
      <origin rpy="-1.570796012878418 -1.7881366431993229e-07 -1.5707964897155762" xyz="-2.3125515313715757e-08 1.0692866677902403e-07 1.0568467285615717e-06"/>
      <geometry>
        <mesh filename="file://meshes/joint_1_obj_hips.008.dae" scale="0.15005260705947876 0.15005260705947876 0.15005264283480813"/>
      </geometry>
    </visual>
  </link>
  <link name="hips.008_link">
    <inertial>
      <mass value="1" />
      <inertia ixx="0" iyy="0" izz="0" ixy="0" ixz="0" iyz="0" />
    </inertial>
    <visual>
      <origin rpy="5.431937779576401e-07 1.8702087345445761e-07 -1.7881369274164172e-07" xyz="-0.0001575026169059121 -0.00786651755044554 8.922830930400624e-05"/>
      <geometry>
        <mesh filename="file://meshes/obj_hips.008.dae" scale="0.15005260705947876 0.15005260705947876 0.15005264283480813"/>
      </geometry>
    </visual>
    <collision>
      <origin rpy="5.431937779576401e-07 1.8702087345445761e-07 -1.7881369274164172e-07" xyz="-0.0001575026169059121 -0.00786651755044554 8.922830930400624e-05"/>
      <geometry>
        <mesh filename="file://collisions/COL_obj_hips.008_convex_hull.dae" scale="0.15005260705947876 0.15005260705947876 0.15005264283480813"/>
      </geometry>
    </collision>
  </link>
  <link name="joint_1_obj_hips.009_link">
    <inertial>
      <mass value="1" />
      <inertia ixx="0" iyy="0" izz="0" ixy="0" ixz="0" iyz="0" />
    </inertial>
    <visual>
      <origin rpy="-1.570796012878418 -2.9802288281643996e-07 -1.5707964897155762" xyz="-9.031985609864274e-08 8.804719556104756e-08 1.3827743987191625e-06"/>
      <geometry>
        <mesh filename="file://meshes/COL_joint_1_obj_hips.009_convex_hull.dae" scale="0.15005260705947876 0.15005260705947876 0.15005260705947876"/>
      </geometry>
    </visual>
    <visual>
      <origin rpy="-1.570796012878418 -2.9802288281643996e-07 -1.5707964897155762" xyz="-9.031985609864274e-08 8.804719556104756e-08 1.3827743987191625e-06"/>
      <geometry>
        <mesh filename="file://meshes/joint_1_obj_hips.009.dae" scale="0.15005260705947876 0.15005260705947876 0.15005260705947876"/>
      </geometry>
    </visual>
  </link>
  <link name="hips.009_link">
    <inertial>
      <mass value="1" />
      <inertia ixx="0" iyy="0" izz="0" ixy="0" ixz="0" iyz="0" />
    </inertial>
    <visual>
      <origin rpy="5.590845830738544e-07 2.307347841679075e-07 -2.9802285439473053e-07" xyz="-0.0001575312825873032 -0.007896894718003589 7.434861090657718e-05"/>
      <geometry>
        <mesh filename="file://meshes/obj_hips.009.dae" scale="0.15005260705947876 0.15005260705947876 0.15005260705947876"/>
      </geometry>
    </visual>
    <collision>
      <origin rpy="5.590845830738544e-07 2.307347841679075e-07 -2.9802285439473053e-07" xyz="-0.0001575312825873032 -0.007896894718003589 7.434861090657718e-05"/>
      <geometry>
        <mesh filename="file://collisions/COL_obj_hips.009_convex_hull.dae" scale="0.15005260705947876 0.15005260705947876 0.15005260705947876"/>
      </geometry>
    </collision>
  </link>
  <link name="joint_1_obj_hips.010_link">
    <inertial>
      <mass value="1" />
      <inertia ixx="0" iyy="0" izz="0" ixy="0" ixz="0" iyz="0" />
    </inertial>
    <visual>
      <origin rpy="-1.5707958936691284 -4.172320871020929e-07 -1.5707966089248657" xyz="-1.699111580780184e-08 1.0356770134036642e-07 1.4225082363992017e-06"/>
      <geometry>
        <mesh filename="file://meshes/COL_joint_1_obj_hips.010_convex_hull.dae" scale="0.15005260705947876 0.15005260705947876 0.15005260705947876"/>
      </geometry>
    </visual>
    <visual>
      <origin rpy="-1.5707958936691284 -4.172320871020929e-07 -1.5707966089248657" xyz="-1.699111580780184e-08 1.0356770134036642e-07 1.4225082363992017e-06"/>
      <geometry>
        <mesh filename="file://meshes/joint_1_obj_hips.010.dae" scale="0.15005260705947876 0.15005260705947876 0.15005260705947876"/>
      </geometry>
    </visual>
  </link>
  <link name="hips.010_link">
    <inertial>
      <mass value="1" />
      <inertia ixx="0" iyy="0" izz="0" ixy="0" ixz="0" iyz="0" />
    </inertial>
    <visual>
      <origin rpy="7.016350878075173e-07 2.744486380379385e-07 -4.172320871020929e-07" xyz="-0.0001575482444255913 -0.005685446646195302 0.00024356764817972526"/>
      <geometry>
        <mesh filename="file://meshes/obj_hips.010.dae" scale="0.15005260705947876 0.15005260705947876 0.15005260705947876"/>
      </geometry>
    </visual>
    <collision>
      <origin rpy="7.016350878075173e-07 2.744486380379385e-07 -4.172320871020929e-07" xyz="-0.0001575482444255913 -0.005685446646195302 0.00024356764817972526"/>
      <geometry>
        <mesh filename="file://collisions/COL_obj_hips.010_convex_hull.dae" scale="0.15005260705947876 0.15005260705947876 0.15005260705947876"/>
      </geometry>
    </collision>
  </link>
  <link name="joint_1_obj_hips.011_link">
    <inertial>
      <mass value="1" />
      <inertia ixx="0" iyy="0" izz="0" ixy="0" ixz="0" iyz="0" />
    </inertial>
    <visual>
      <origin rpy="-1.5707958936691284 -5.36441234544327e-07 -1.5707966089248657" xyz="-1.5847769169676667e-07 1.5536259771718616e-07 1.7482765754371242e-06"/>
      <geometry>
        <mesh filename="file://meshes/COL_joint_1_obj_hips.011_convex_hull.dae" scale="0.15005260705947876 0.15005260705947876 0.15005260705947876"/>
      </geometry>
    </visual>
    <visual>
      <origin rpy="-1.5707958936691284 -5.36441234544327e-07 -1.5707966089248657" xyz="-1.5847769169676667e-07 1.5536259771718616e-07 1.7482765754371242e-06"/>
      <geometry>
        <mesh filename="file://meshes/joint_1_obj_hips.011.dae" scale="0.15005260705947876 0.15005260705947876 0.15005260705947876"/>
      </geometry>
    </visual>
  </link>
  <link name="hips.011_link">
    <inertial>
      <mass value="1" />
      <inertia ixx="0" iyy="0" izz="0" ixy="0" ixz="0" iyz="0" />
    </inertial>
    <visual>
      <origin rpy="7.621713962180365e-07 3.182206285146094e-07 -5.364266257856798e-07" xyz="-0.00017583729852155977 -0.0061826203113157785 0.00019248051278248496"/>
      <geometry>
        <mesh filename="file://meshes/obj_hips.011.dae" scale="0.15005260705947876 0.15005260705947876 0.15005260705947876"/>
      </geometry>
    </visual>
    <collision>
      <origin rpy="7.621713962180365e-07 3.182206285146094e-07 -5.364266257856798e-07" xyz="-0.00017583729852155977 -0.0061826203113157785 0.00019248051278248496"/>
      <geometry>
        <mesh filename="file://collisions/COL_obj_hips.011_convex_hull.dae" scale="0.15005260705947876 0.15005260705947876 0.15005260705947876"/>
      </geometry>
    </collision>
  </link>
  <link name="joint_1_obj_hips.012_link">
    <inertial>
      <mass value="1" />
      <inertia ixx="0" iyy="0" izz="0" ixy="0" ixz="0" iyz="0" />
    </inertial>
    <visual>
      <origin rpy="-1.5707958936691284 -5.364410640140704e-07 -1.5707966089248657" xyz="-1.2499657692332768e-07 1.7904715159688288e-07 1.9933192397478565e-06"/>
      <geometry>
        <mesh filename="file://meshes/COL_joint_1_obj_hips.012_convex_hull.dae" scale="0.15005260705947876 0.15005262494714344 0.15005260705947876"/>
      </geometry>
    </visual>
    <visual>
      <origin rpy="-1.5707958936691284 -5.364410640140704e-07 -1.5707966089248657" xyz="-1.2499657692332768e-07 1.7904715159688288e-07 1.9933192397478565e-06"/>
      <geometry>
        <mesh filename="file://meshes/joint_1_obj_hips.012.dae" scale="0.15005260705947876 0.15005262494714344 0.15005260705947876"/>
      </geometry>
    </visual>
  </link>
  <link name="hips.012_link">
    <inertial>
      <mass value="1" />
      <inertia ixx="0" iyy="0" izz="0" ixy="0" ixz="0" iyz="0" />
    </inertial>
    <visual>
      <origin rpy="7.408673923237075e-07 3.6187617524774396e-07 -5.364411208574893e-07" xyz="9.497153359624283e-05 -0.005519161797324923 0.0007366565847151396"/>
      <geometry>
        <mesh filename="file://meshes/obj_hips.012.dae" scale="0.15005260705947876 0.15005259811564642 0.15005260705947876"/>
      </geometry>
    </visual>
    <collision>
      <origin rpy="7.408673923237075e-07 3.6187617524774396e-07 -5.364411208574893e-07" xyz="9.497153359624283e-05 -0.005519161797324923 0.0007366565847151396"/>
      <geometry>
        <mesh filename="file://collisions/COL_obj_hips.012_convex_hull.dae" scale="0.15005260705947876 0.15005259811564642 0.15005260705947876"/>
      </geometry>
    </collision>
  </link>
  <link name="joint_1_obj_hips.013_link">
    <inertial>
      <mass value="1" />
      <inertia ixx="0" iyy="0" izz="0" ixy="0" ixz="0" iyz="0" />
    </inertial>
    <visual>
      <origin rpy="-1.5707958936691284 -6.556502967214328e-07 -1.5707967281341553" xyz="-1.2580708443485697e-07 2.0475157712800715e-07 2.03310903096885e-06"/>
      <geometry>
        <mesh filename="file://meshes/COL_joint_1_obj_hips.013_convex_hull.dae" scale="0.15005260705947876 0.15005260705947876 0.15005260705947876"/>
      </geometry>
    </visual>
    <visual>
      <origin rpy="-1.5707958936691284 -6.556502967214328e-07 -1.5707967281341553" xyz="-1.2580708443485697e-07 2.0475157712800715e-07 2.03310903096885e-06"/>
      <geometry>
        <mesh filename="file://meshes/joint_1_obj_hips.013.dae" scale="0.15005260705947876 0.15005260705947876 0.15005260705947876"/>
      </geometry>
    </visual>
  </link>
  <link name="hips.013_link">
    <inertial>
      <mass value="1" />
      <inertia ixx="0" iyy="0" izz="0" ixy="0" ixz="0" iyz="0" />
    </inertial>
    <visual>
      <origin rpy="8.462235427941778e-07 4.0553166513745964e-07 -5.364556159292988e-07" xyz="-0.0003542537397577261 -0.0038308915831697377 0.00032223478503866365"/>
      <geometry>
        <mesh filename="file://meshes/obj_hips.013.dae" scale="0.15005260705947876 0.15005260705947876 0.15005260705947876"/>
      </geometry>
    </visual>
    <collision>
      <origin rpy="8.462235427941778e-07 4.0553166513745964e-07 -5.364556159292988e-07" xyz="-0.0003542537397577261 -0.0038308915831697377 0.00032223478503866365"/>
      <geometry>
        <mesh filename="file://collisions/COL_obj_hips.013_convex_hull.dae" scale="0.15005260705947876 0.15005260705947876 0.15005260705947876"/>
      </geometry>
    </collision>
  </link>
  <link name="joint_1_obj_hips.014_link">
    <inertial>
      <mass value="1" />
      <inertia ixx="0" iyy="0" izz="0" ixy="0" ixz="0" iyz="0" />
    </inertial>
    <visual>
      <origin rpy="-1.5707957744598389 -6.556497851306631e-07 -1.5707967281341553" xyz="-1.2740041269054705e-07 2.42453960091281e-07 2.358732436688496e-06"/>
      <geometry>
        <mesh filename="file://meshes/COL_joint_1_obj_hips.014_convex_hull.dae" scale="0.15005260705947876 0.15005262494714344 0.15005264283480813"/>
      </geometry>
    </visual>
    <visual>
      <origin rpy="-1.5707957744598389 -6.556497851306631e-07 -1.5707967281341553" xyz="-1.2740041269054705e-07 2.42453960091281e-07 2.358732436688496e-06"/>
      <geometry>
        <mesh filename="file://meshes/joint_1_obj_hips.014.dae" scale="0.15005260705947876 0.15005262494714344 0.15005264283480813"/>
      </geometry>
    </visual>
  </link>
  <link name="hips.014_link">
    <inertial>
      <mass value="1" />
      <inertia ixx="0" iyy="0" izz="0" ixy="0" ixz="0" iyz="0" />
    </inertial>
    <visual>
      <origin rpy="8.993090432340978e-07 4.493033429753268e-07 -6.556353469022724e-07" xyz="-0.00012982925545993937 -0.002821208095916128 0.0001134482422213666"/>
      <geometry>
        <mesh filename="file://meshes/obj_hips.014.dae" scale="0.15005260705947876 0.15005258917181408 0.15005260705947876"/>
      </geometry>
    </visual>
    <collision>
      <origin rpy="8.993090432340978e-07 4.493033429753268e-07 -6.556353469022724e-07" xyz="-0.00012982925545993937 -0.002821208095916128 0.0001134482422213666"/>
      <geometry>
        <mesh filename="file://collisions/COL_obj_hips.014_convex_hull.dae" scale="0.15005260705947876 0.15005258917181408 0.15005260705947876"/>
      </geometry>
    </collision>
  </link>
  <link name="joint_1_obj_hips.015_link">
    <inertial>
      <mass value="1" />
      <inertia ixx="0" iyy="0" izz="0" ixy="0" ixz="0" iyz="0" />
    </inertial>
    <visual>
      <origin rpy="-1.5707957744598389 -7.74859188368282e-07 -1.5707968473434448" xyz="-1.3016438114163355e-07 2.4767510782256364e-07 2.112304444586968e-06"/>
      <geometry>
        <mesh filename="file://meshes/COL_joint_1_obj_hips.015_convex_hull.dae" scale="0.15005260705947876 0.15005260705947876 0.15005264283480813"/>
      </geometry>
    </visual>
    <visual>
      <origin rpy="-1.5707957744598389 -7.74859188368282e-07 -1.5707968473434448" xyz="-1.3016438114163355e-07 2.4767510782256364e-07 2.112304444586968e-06"/>
      <geometry>
        <mesh filename="file://meshes/joint_1_obj_hips.015.dae" scale="0.15005260705947876 0.15005260705947876 0.15005264283480813"/>
      </geometry>
    </visual>
  </link>
  <link name="hips.015_link">
    <inertial>
      <mass value="1" />
      <inertia ixx="0" iyy="0" izz="0" ixy="0" ixz="0" iyz="0" />
    </inertial>
    <visual>
      <origin rpy="1.0120576234839973e-06 3.7380786466201243e-07 -7.74873910813767e-07" xyz="-0.0001743342630407957 -0.004500398922770987 0.0006112924240068984"/>
      <geometry>
        <mesh filename="file://meshes/obj_hips.015.dae" scale="0.15005260705947876 0.15005260705947876 0.15005260705947876"/>
      </geometry>
    </visual>
    <collision>
      <origin rpy="1.0120576234839973e-06 3.7380786466201243e-07 -7.74873910813767e-07" xyz="-0.0001743342630407957 -0.004500398922770987 0.0006112924240068984"/>
      <geometry>
        <mesh filename="file://collisions/COL_obj_hips.015_convex_hull.dae" scale="0.15005260705947876 0.15005260705947876 0.15005260705947876"/>
      </geometry>
    </collision>
  </link>
  <link name="joint_1_obj_hips.016_link">
    <inertial>
      <mass value="1" />
      <inertia ixx="0" iyy="0" izz="0" ixy="0" ixz="0" iyz="0" />
    </inertial>
    <visual>
      <origin rpy="-1.5707956552505493 -7.748589041511877e-07 -1.5707967281341553" xyz="-6.492928643180526e-08 2.4379831214873127e-07 2.724279649183323e-06"/>
      <geometry>
        <mesh filename="file://meshes/COL_joint_1_obj_hips.016_convex_hull.dae" scale="0.15005260705947876 0.15005260705947876 0.15005264283480813"/>
      </geometry>
    </visual>
    <visual>
      <origin rpy="-1.5707956552505493 -7.748589041511877e-07 -1.5707967281341553" xyz="-6.492928643180526e-08 2.4379831214873127e-07 2.724279649183323e-06"/>
      <geometry>
        <mesh filename="file://meshes/joint_1_obj_hips.016.dae" scale="0.15005260705947876 0.15005260705947876 0.15005264283480813"/>
      </geometry>
    </visual>
  </link>
  <link name="hips.016_link">
    <inertial>
      <mass value="1" />
      <inertia ixx="0" iyy="0" izz="0" ixy="0" ixz="0" iyz="0" />
    </inertial>
    <visual>
      <origin rpy="1.1249244380451273e-06 4.175796277650079e-07 -7.748734560664161e-07" xyz="-0.0001576899657376729 -0.005665282776181613 0.0005614109591334931"/>
      <geometry>
        <mesh filename="file://meshes/obj_hips.016.dae" scale="0.15005260705947876 0.15005260705947876 0.15005260705947876"/>
      </geometry>
    </visual>
    <collision>
      <origin rpy="1.1249244380451273e-06 4.175796277650079e-07 -7.748734560664161e-07" xyz="-0.0001576899657376729 -0.005665282776181613 0.0005614109591334931"/>
      <geometry>
        <mesh filename="file://collisions/COL_obj_hips.016_convex_hull.dae" scale="0.15005260705947876 0.15005260705947876 0.15005260705947876"/>
      </geometry>
    </collision>
  </link>
  <link name="joint_1_obj_hips.017_link">
    <inertial>
      <mass value="1" />
      <inertia ixx="0" iyy="0" izz="0" ixy="0" ixz="0" iyz="0" />
    </inertial>
    <visual>
      <origin rpy="-1.5707956552505493 -7.748589609946066e-07 -1.5707967281341553" xyz="-7.545929504046848e-08 3.1460519820140573e-07 2.4773820567539333e-06"/>
      <geometry>
        <mesh filename="file://meshes/COL_joint_1_obj_hips.017_convex_hull.dae" scale="0.15005260705947876 0.15005262494714344 0.15005260705947876"/>
      </geometry>
    </visual>
    <visual>
      <origin rpy="-1.5707956552505493 -7.748589609946066e-07 -1.5707967281341553" xyz="-7.545929504046848e-08 3.1460519820140573e-07 2.4773820567539333e-06"/>
      <geometry>
        <mesh filename="file://meshes/joint_1_obj_hips.017.dae" scale="0.15005260705947876 0.15005262494714344 0.15005260705947876"/>
      </geometry>
    </visual>
  </link>
  <link name="hips.017_link">
    <inertial>
      <mass value="1" />
      <inertia ixx="0" iyy="0" izz="0" ixy="0" ixz="0" iyz="0" />
    </inertial>
    <visual>
      <origin rpy="1.2148028645242448e-06 4.612933537373465e-07 -7.748590746814443e-07" xyz="-0.00015771625571359832 -0.0064626830053382545 0.00039740504066791693"/>
      <geometry>
        <mesh filename="file://meshes/obj_hips.017.dae" scale="0.15005260705947876 0.15005260705947876 0.15005260705947876"/>
      </geometry>
    </visual>
    <collision>
      <origin rpy="1.2148028645242448e-06 4.612933537373465e-07 -7.748590746814443e-07" xyz="-0.00015771625571359832 -0.0064626830053382545 0.00039740504066791693"/>
      <geometry>
        <mesh filename="file://collisions/COL_obj_hips.017_convex_hull.dae" scale="0.15005260705947876 0.15005260705947876 0.15005260705947876"/>
      </geometry>
    </collision>
  </link>
  <link name="joint_1_obj_hips.018_link">
    <inertial>
      <mass value="1" />
      <inertia ixx="0" iyy="0" izz="0" ixy="0" ixz="0" iyz="0" />
    </inertial>
    <visual>
      <origin rpy="-1.5707956552505493 -7.748588473077689e-07 -1.5707968473434448" xyz="-1.1556081401470168e-07 3.123946239175614e-07 2.722840141988238e-06"/>
      <geometry>
        <mesh filename="file://meshes/COL_joint_1_obj_hips.018_convex_hull.dae" scale="0.15005260705947876 0.15005260705947876 0.15005260705947876"/>
      </geometry>
    </visual>
    <visual>
      <origin rpy="-1.5707956552505493 -7.748588473077689e-07 -1.5707968473434448" xyz="-1.1556081401470168e-07 3.123946239175614e-07 2.722840141988238e-06"/>
      <geometry>
        <mesh filename="file://meshes/joint_1_obj_hips.018.dae" scale="0.15005260705947876 0.15005260705947876 0.15005260705947876"/>
      </geometry>
    </visual>
  </link>
  <link name="hips.018_link">
    <inertial>
      <mass value="1" />
      <inertia ixx="0" iyy="0" izz="0" ixy="0" ixz="0" iyz="0" />
    </inertial>
    <visual>
      <origin rpy="1.1401909887354122e-06 3.8678695091221016e-07 -7.748445796096348e-07" xyz="-0.00015774831026896252 -0.006050797166435862 0.0007425987132006484"/>
      <geometry>
        <mesh filename="file://meshes/obj_hips.018.dae" scale="0.15005260705947876 0.15005260705947876 0.15005264283480813"/>
      </geometry>
    </visual>
    <collision>
      <origin rpy="1.1401909887354122e-06 3.8678695091221016e-07 -7.748445796096348e-07" xyz="-0.00015774831026896252 -0.006050797166435862 0.0007425987132006484"/>
      <geometry>
        <mesh filename="file://collisions/COL_obj_hips.018_convex_hull.dae" scale="0.15005260705947876 0.15005260705947876 0.15005264283480813"/>
      </geometry>
    </collision>
  </link>
  <link name="joint_1_obj_hips.019_link">
    <inertial>
      <mass value="1" />
      <inertia ixx="0" iyy="0" izz="0" ixy="0" ixz="0" iyz="0" />
    </inertial>
    <visual>
      <origin rpy="-1.5707956552505493 -7.74859188368282e-07 -1.5707967281341553" xyz="-5.497720284157085e-08 3.3904249779700035e-07 3.0488290198607505e-06"/>
      <geometry>
        <mesh filename="file://meshes/COL_joint_1_obj_hips.019_convex_hull.dae" scale="0.15005260705947876 0.15005260705947876 0.15005260705947876"/>
      </geometry>
    </visual>
    <visual>
      <origin rpy="-1.5707956552505493 -7.74859188368282e-07 -1.5707967281341553" xyz="-5.497720284157085e-08 3.3904249779700035e-07 3.0488290198607505e-06"/>
      <geometry>
        <mesh filename="file://meshes/joint_1_obj_hips.019.dae" scale="0.15005260705947876 0.15005260705947876 0.15005260705947876"/>
      </geometry>
    </visual>
  </link>
  <link name="hips.019_link">
    <inertial>
      <mass value="1" />
      <inertia ixx="0" iyy="0" izz="0" ixy="0" ixz="0" iyz="0" />
    </inertial>
    <visual>
      <origin rpy="1.2532514119811822e-06 4.3050076214967703e-07 -6.55664507576148e-07" xyz="-0.00015781070747428183 -0.005918610119377554 0.000416238864989274"/>
      <geometry>
        <mesh filename="file://meshes/obj_hips.019.dae" scale="0.15005260705947876 0.15005259811564642 0.15005260705947876"/>
      </geometry>
    </visual>
    <collision>
      <origin rpy="1.2532514119811822e-06 4.3050076214967703e-07 -6.55664507576148e-07" xyz="-0.00015781070747428183 -0.005918610119377554 0.000416238864989274"/>
      <geometry>
        <mesh filename="file://collisions/COL_obj_hips.019_convex_hull.dae" scale="0.15005260705947876 0.15005259811564642 0.15005260705947876"/>
      </geometry>
    </collision>
  </link>
  <link name="joint_1_obj_hips.020_link">
    <inertial>
      <mass value="1" />
      <inertia ixx="0" iyy="0" izz="0" ixy="0" ixz="0" iyz="0" />
    </inertial>
    <visual>
      <origin rpy="-1.5707956552505493 -6.556497851306631e-07 -1.5707967281341553" xyz="-1.7196664040528188e-07 3.406233218010077e-07 3.5792483902430264e-06"/>
      <geometry>
        <mesh filename="file://meshes/COL_joint_1_obj_hips.020_convex_hull.dae" scale="0.15005260705947876 0.15005260705947876 0.15005260705947876"/>
      </geometry>
    </visual>
    <visual>
      <origin rpy="-1.5707956552505493 -6.556497851306631e-07 -1.5707967281341553" xyz="-1.7196664040528188e-07 3.406233218010077e-07 3.5792483902430264e-06"/>
      <geometry>
        <mesh filename="file://meshes/joint_1_obj_hips.020.dae" scale="0.15005260705947876 0.15005260705947876 0.15005260705947876"/>
      </geometry>
    </visual>
  </link>
  <link name="hips.020_link">
    <inertial>
      <mass value="1" />
      <inertia ixx="0" iyy="0" izz="0" ixy="0" ixz="0" iyz="0" />
    </inertial>
    <visual>
      <origin rpy="1.2401389994920464e-06 4.74155939400589e-07 -5.364405524233007e-07" xyz="-0.00015796329414518445 -0.0064042546256204425 0.000751909522162808"/>
      <geometry>
        <mesh filename="file://meshes/obj_hips.020.dae" scale="0.15005260705947876 0.15005260705947876 0.15005264283480813"/>
      </geometry>
    </visual>
    <collision>
      <origin rpy="1.2401389994920464e-06 4.74155939400589e-07 -5.364405524233007e-07" xyz="-0.00015796329414518445 -0.0064042546256204425 0.000751909522162808"/>
      <geometry>
        <mesh filename="file://collisions/COL_obj_hips.020_convex_hull.dae" scale="0.15005260705947876 0.15005260705947876 0.15005264283480813"/>
      </geometry>
    </collision>
  </link>
  <link name="joint_1_obj_hips.021_link">
    <inertial>
      <mass value="1" />
      <inertia ixx="0" iyy="0" izz="0" ixy="0" ixz="0" iyz="0" />
    </inertial>
    <visual>
      <origin rpy="-1.5707956552505493 -5.364403818930441e-07 -1.5707968473434448" xyz="-2.628358562161559e-07 4.009844323538136e-07 3.0465630379241564e-06"/>
      <geometry>
        <mesh filename="file://meshes/COL_joint_1_obj_hips.021_convex_hull.dae" scale="0.15005260705947876 0.15005259811564642 0.15005260705947876"/>
      </geometry>
    </visual>
    <visual>
      <origin rpy="-1.5707956552505493 -5.364403818930441e-07 -1.5707968473434448" xyz="-2.628358562161559e-07 4.009844323538136e-07 3.0465630379241564e-06"/>
      <geometry>
        <mesh filename="file://meshes/joint_1_obj_hips.021.dae" scale="0.15005260705947876 0.15005259811564642 0.15005260705947876"/>
      </geometry>
    </visual>
  </link>
  <link name="hips.021_link">
    <inertial>
      <mass value="1" />
      <inertia ixx="0" iyy="0" izz="0" ixy="0" ixz="0" iyz="0" />
    </inertial>
    <visual>
      <origin rpy="1.3226456303527812e-06 3.987186119047692e-07 -5.364406092667195e-07" xyz="-0.00015691952096146683 -0.013270874079878148 0.007920472337024087"/>
      <geometry>
        <mesh filename="file://meshes/obj_hips.021.dae" scale="0.15005260705947876 0.15005259811564642 0.15005260705947876"/>
      </geometry>
    </visual>
    <collision>
      <origin rpy="1.3226456303527812e-06 3.987186119047692e-07 -5.364406092667195e-07" xyz="-0.00015691952096146683 -0.013270874079878148 0.007920472337024087"/>
      <geometry>
        <mesh filename="file://collisions/COL_obj_hips.021_convex_hull.dae" scale="0.15005260705947876 0.15005259811564642 0.15005260705947876"/>
      </geometry>
    </collision>
  </link>
  <link name="hips_link">
    <inertial>
      <mass value="1" />
      <inertia ixx="0" iyy="0" izz="0" ixy="0" ixz="0" iyz="0" />
    </inertial>
    <visual>
      <origin rpy="1.3675173704541521e-06 4.200880709959165e-07 -5.364405524233007e-07" xyz="-3.1618825215872816e-05 -0.0069395150417772555 0.0033694761982344668"/>
      <geometry>
        <mesh filename="file://meshes/obj_hips.dae" scale="0.15005260705947876 0.15005259811564642 0.15005260705947876"/>
      </geometry>
    </visual>
    <collision>
      <origin rpy="1.3675173704541521e-06 4.200880709959165e-07 -5.364405524233007e-07" xyz="-3.1618825215872816e-05 -0.0069395150417772555 0.0033694761982344668"/>
      <geometry>
        <mesh filename="file://collisions/COL_obj_hips_convex_hull.dae" scale="0.15005260705947876 0.15005259811564642 0.15005260705947876"/>
      </geometry>
    </collision>
  </link>
  <link name="spine_link">
    <inertial>
      <mass value="1" />
      <inertia ixx="0" iyy="0" izz="0" ixy="0" ixz="0" iyz="0" />
    </inertial>
    <visual>
      <origin rpy="1.3675174841409898e-06 4.2008821310446365e-07 -5.364550474951102e-07" xyz="-0.0003432116703742938 -0.03059074403840345 0.01623344140241345"/>
      <geometry>
        <mesh filename="file://meshes/obj_spine.dae" scale="0.15005260705947876 0.15005260705947876 0.15005264283480813"/>
      </geometry>
    </visual>
    <collision>
      <origin rpy="1.3675174841409898e-06 4.2008821310446365e-07 -5.364550474951102e-07" xyz="-0.0003432116703742938 -0.03059074403840345 0.01623344140241345"/>
      <geometry>
        <mesh filename="file://collisions/COL_obj_spine_convex_hull.dae" scale="0.15005260705947876 0.15005260705947876 0.15005264283480813"/>
      </geometry>
    </collision>
  </link>
  <link name="chest_link">
    <inertial>
      <mass value="1" />
      <inertia ixx="0" iyy="0" izz="0" ixy="0" ixz="0" iyz="0" />
    </inertial>
    <visual>
      <origin rpy="1.3675174841409898e-06 4.200884688998485e-07 -5.3642611419491e-07" xyz="9.452142475260827e-05 -0.02877106544959318 0.009606176789276333"/>
      <geometry>
        <mesh filename="file://meshes/obj_chest.dae" scale="0.15005260705947876 0.15005260705947876 0.15005260705947876"/>
      </geometry>
    </visual>
    <collision>
      <origin rpy="1.3675174841409898e-06 4.200884688998485e-07 -5.3642611419491e-07" xyz="9.452142475260827e-05 -0.02877106544959318 0.009606176789276333"/>
      <geometry>
        <mesh filename="file://collisions/COL_obj_chest_convex_hull.dae" scale="0.15005260705947876 0.15005260705947876 0.15005260705947876"/>
      </geometry>
    </collision>
  </link>
  <link name="neck_link">
    <inertial>
      <mass value="1" />
      <inertia ixx="0" iyy="0" izz="0" ixy="0" ixz="0" iyz="0" />
    </inertial>
    <visual>
      <origin rpy="1.4271217878558673e-06 4.2008869627352396e-07 -5.364695994103386e-07" xyz="-0.00016608686176929066 -0.021267375699678404 -0.025504122742794344"/>
      <geometry>
        <mesh filename="file://meshes/obj_neck.dae" scale="0.15005260705947876 0.15005262494714344 0.15005260705947876"/>
      </geometry>
    </visual>
    <collision>
      <origin rpy="1.4271217878558673e-06 4.2008869627352396e-07 -5.364695994103386e-07" xyz="-0.00016608686176929066 -0.021267375699678404 -0.025504122742794344"/>
      <geometry>
        <mesh filename="file://collisions/COL_obj_neck_convex_hull.dae" scale="0.15005260705947876 0.15005262494714344 0.15005260705947876"/>
      </geometry>
    </collision>
  </link>
  <link name="head_link">
    <inertial>
      <mass value="1" />
      <inertia ixx="0" iyy="0" izz="0" ixy="0" ixz="0" iyz="0" />
    </inertial>
    <visual>
      <origin rpy="1.3675171430804767e-06 4.200887531169428e-07 -5.364115054362628e-07" xyz="-0.0002655488804693962 -0.024551850553824472 0.005729518498036601"/>
      <geometry>
        <mesh filename="file://meshes/obj_head.dae" scale="0.15005260705947876 0.15005260705947876 0.15005264283480813"/>
      </geometry>
    </visual>
    <collision>
      <origin rpy="1.3675171430804767e-06 4.200887531169428e-07 -5.364115054362628e-07" xyz="-0.0002655488804693962 -0.024551850553824472 0.005729518498036601"/>
      <geometry>
        <mesh filename="file://collisions/COL_obj_head_convex_hull.dae" scale="0.15005260705947876 0.15005260705947876 0.15005264283480813"/>
      </geometry>
    </collision>
  </link>
  <link name="nose_link">
    <inertial>
      <mass value="1" />
      <inertia ixx="0" iyy="0" izz="0" ixy="0" ixz="0" iyz="0" />
    </inertial>
    <visual>
      <origin rpy="1.412220512975182e-06 4.2008898049061827e-07 -5.364406092667195e-07" xyz="-2.5268647481104488e-05 -0.007963544156611713 -0.000307764502794558"/>
      <geometry>
        <mesh filename="file://meshes/obj_nose.dae" scale="0.15005260705947876 0.15005260705947876 0.15005260705947876"/>
      </geometry>
    </visual>
    <collision>
      <origin rpy="1.412220512975182e-06 4.2008898049061827e-07 -5.364406092667195e-07" xyz="-2.5268647481104488e-05 -0.007963544156611713 -0.000307764502794558"/>
      <geometry>
        <mesh filename="file://collisions/COL_obj_nose_convex_hull.dae" scale="0.15005260705947876 0.15005260705947876 0.15005260705947876"/>
      </geometry>
    </collision>
  </link>
  <link name="mouth_link">
    <inertial>
      <mass value="1" />
      <inertia ixx="0" iyy="0" izz="0" ixy="0" ixz="0" iyz="0" />
    </inertial>
    <visual>
      <origin rpy="1.3675171430804767e-06 4.200887531169428e-07 -5.364406092667195e-07" xyz="-2.038148288750416e-05 -0.013786037704763832 -0.01414459258939349"/>
      <geometry>
        <mesh filename="file://meshes/obj_mouth.dae" scale="0.15005260705947876 0.15005260705947876 0.15005264283480813"/>
      </geometry>
    </visual>
    <collision>
      <origin rpy="1.3675171430804767e-06 4.200887531169428e-07 -5.364406092667195e-07" xyz="-2.038148288750416e-05 -0.013786037704763832 -0.01414459258939349"/>
      <geometry>
        <mesh filename="file://collisions/COL_obj_mouth_convex_hull.dae" scale="0.15005260705947876 0.15005260705947876 0.15005264283480813"/>
      </geometry>
    </collision>
  </link>
  <link name="neck.001_link">
    <inertial>
      <mass value="1" />
      <inertia ixx="0" iyy="0" izz="0" ixy="0" ixz="0" iyz="0" />
    </inertial>
    <visual>
      <origin rpy="1.3675171430804767e-06 4.200887531169428e-07 -5.364115054362628e-07" xyz="-0.017170677891238384 0.007053220218291578 0.017582722483164837"/>
      <geometry>
        <mesh filename="file://meshes/obj_neck.001.dae" scale="0.15005260705947876 0.15005260705947876 0.15005264283480813"/>
      </geometry>
    </visual>
    <collision>
      <origin rpy="1.3675171430804767e-06 4.200887531169428e-07 -5.364115054362628e-07" xyz="-0.017170677891238384 0.007053220218291578 0.017582722483164837"/>
      <geometry>
        <mesh filename="file://collisions/COL_obj_neck.001_convex_hull.dae" scale="0.15005260705947876 0.15005260705947876 0.15005264283480813"/>
      </geometry>
    </collision>
  </link>
  <link name="neck.002_link">
    <inertial>
      <mass value="1" />
      <inertia ixx="0" iyy="0" izz="0" ixy="0" ixz="0" iyz="0" />
    </inertial>
    <visual>
      <origin rpy="1.3675171430804767e-06 4.200887531169428e-07 -5.364115054362628e-07" xyz="0.017338454124151692 0.007508550163802807 0.01730666662603131"/>
      <geometry>
        <mesh filename="file://meshes/obj_neck.002.dae" scale="0.15005260705947876 0.15005260705947876 0.15005264283480813"/>
      </geometry>
    </visual>
    <collision>
      <origin rpy="1.3675171430804767e-06 4.200887531169428e-07 -5.364115054362628e-07" xyz="0.017338454124151692 0.007508550163802807 0.01730666662603131"/>
      <geometry>
        <mesh filename="file://collisions/COL_obj_neck.002_convex_hull.dae" scale="0.15005260705947876 0.15005260705947876 0.15005264283480813"/>
      </geometry>
    </collision>
  </link>
  <link name="shoulder.L_link">
    <inertial>
      <mass value="1" />
      <inertia ixx="0" iyy="0" izz="0" ixy="0" ixz="0" iyz="0" />
    </inertial>
    <visual>
      <origin rpy="1.4122206266620196e-06 4.2008869627352396e-07 -5.364987032407953e-07" xyz="0.016417534539454604 -0.0018368299245460906 0.011339835834585088"/>
      <geometry>
        <mesh filename="file://meshes/obj_shoulder.L.dae" scale="0.15005260705947876 0.15005262494714344 0.15005260705947876"/>
      </geometry>
    </visual>
    <collision>
      <origin rpy="1.4122206266620196e-06 4.2008869627352396e-07 -5.364987032407953e-07" xyz="0.016417534539454604 -0.0018368299245460906 0.011339835834585088"/>
      <geometry>
        <mesh filename="file://collisions/COL_obj_shoulder.L_convex_hull.dae" scale="0.15005260705947876 0.15005262494714344 0.15005260705947876"/>
      </geometry>
    </collision>
  </link>
  <link name="upper_arm.L_link">
    <inertial>
      <mass value="1" />
      <inertia ixx="0" iyy="0" izz="0" ixy="0" ixz="0" iyz="0" />
    </inertial>
    <visual>
      <origin rpy="1.2518445373643772e-06 0.19198668003082275 -5.413717190094758e-07" xyz="0.006436198081817279 0.018175036723806492 -0.009148510826555434"/>
      <geometry>
        <mesh filename="file://meshes/obj_upper_arm.L.dae" scale="0.15005259811564642 0.15005260705947876 0.15005260705947876"/>
      </geometry>
    </visual>
    <collision>
      <origin rpy="1.2518445373643772e-06 0.19198668003082275 -5.413717190094758e-07" xyz="0.006436198081817279 0.018175036723806492 -0.009148510826555434"/>
      <geometry>
        <mesh filename="file://collisions/COL_obj_upper_arm.L_convex_hull.dae" scale="0.15005259811564642 0.15005260705947876 0.15005260705947876"/>
      </geometry>
    </collision>
  </link>
  <link name="forearm.L_link">
    <inertial>
      <mass value="1" />
      <inertia ixx="0" iyy="0" izz="0" ixy="0" ixz="0" iyz="0" />
    </inertial>
    <visual>
      <origin rpy="1.3659810065291822e-06 0.19198690354824066 -5.264683977657114e-07" xyz="-0.002686589164945241 -0.020249668197340753 -0.01006531736635452"/>
      <geometry>
        <mesh filename="file://meshes/obj_forearm.L.dae" scale="0.15005260705947876 0.15005260705947876 0.15005260705947876"/>
      </geometry>
    </visual>
    <collision>
      <origin rpy="1.3659810065291822e-06 0.19198690354824066 -5.264683977657114e-07" xyz="-0.002686589164945241 -0.020249668197340753 -0.01006531736635452"/>
      <geometry>
        <mesh filename="file://collisions/COL_obj_forearm.L_convex_hull.dae" scale="0.15005260705947876 0.15005260705947876 0.15005260705947876"/>
      </geometry>
    </collision>
  </link>
  <link name="wrist.L_link">
    <inertial>
      <mass value="1" />
      <inertia ixx="0" iyy="0" izz="0" ixy="0" ixz="0" iyz="0" />
    </inertial>
    <visual>
      <origin rpy="1.4231999330149847e-06 6.854542675682751e-07 -5.227692554399255e-07" xyz="0.00023369355246428275 -0.0032658389819889555 0.0001334975106489708"/>
      <geometry>
        <mesh filename="file://meshes/obj_wrist.L.dae" scale="0.15005260705947876 0.15005260705947876 0.15005260705947876"/>
      </geometry>
    </visual>
    <collision>
      <origin rpy="1.4231999330149847e-06 6.854542675682751e-07 -5.227692554399255e-07" xyz="0.00023369355246428275 -0.0032658389819889555 0.0001334975106489708"/>
      <geometry>
        <mesh filename="file://collisions/COL_obj_wrist.L_convex_hull.dae" scale="0.15005260705947876 0.15005260705947876 0.15005260705947876"/>
      </geometry>
    </collision>
  </link>
  <link name="shoulder.R_link">
    <inertial>
      <mass value="1" />
      <inertia ixx="0" iyy="0" izz="0" ixy="0" ixz="0" iyz="0" />
    </inertial>
    <visual>
      <origin rpy="1.4271217878558673e-06 4.2008869627352396e-07 -5.364987032407953e-07" xyz="-0.015202749691474171 -0.002317920063663881 0.011904812133696208"/>
      <geometry>
        <mesh filename="file://meshes/obj_shoulder.R.dae" scale="0.15005260705947876 0.15005262494714344 0.15005260705947876"/>
      </geometry>
    </visual>
    <collision>
      <origin rpy="1.4271217878558673e-06 4.2008869627352396e-07 -5.364987032407953e-07" xyz="-0.015202749691474171 -0.002317920063663881 0.011904812133696208"/>
      <geometry>
        <mesh filename="file://collisions/COL_obj_shoulder.R_convex_hull.dae" scale="0.15005260705947876 0.15005262494714344 0.15005260705947876"/>
      </geometry>
    </collision>
  </link>
  <link name="upper_arm.R_link">
    <inertial>
      <mass value="1" />
      <inertia ixx="0" iyy="0" izz="0" ixy="0" ixz="0" iyz="0" />
    </inertial>
    <visual>
      <origin rpy="1.478003355259716e-06 -0.19198578596115112 -5.358935482036031e-07" xyz="-0.0065512420382352055 0.017827907584992975 -0.009097053046168702"/>
      <geometry>
        <mesh filename="file://meshes/obj_upper_arm.R.dae" scale="0.15005258917181408 0.15005260705947876 0.1500525712841494"/>
      </geometry>
    </visual>
    <collision>
      <origin rpy="1.478003355259716e-06 -0.19198578596115112 -5.358935482036031e-07" xyz="-0.0065512420382352055 0.017827907584992975 -0.009097053046168702"/>
      <geometry>
        <mesh filename="file://collisions/COL_obj_upper_arm.R_convex_hull.dae" scale="0.15005258917181408 0.15005260705947876 0.1500525712841494"/>
      </geometry>
    </collision>
  </link>
  <link name="forearm.R_link">
    <inertial>
      <mass value="1" />
      <inertia ixx="0" iyy="0" izz="0" ixy="0" ixz="0" iyz="0" />
    </inertial>
    <visual>
      <origin rpy="1.524422486909316e-06 -0.19198594987392426 -5.587070859291998e-07" xyz="0.0023382222835841016 -0.02017780003256142 -0.010105537780393803"/>
      <geometry>
        <mesh filename="file://meshes/obj_forearm.R.dae" scale="0.15005260705947876 0.15005260705947876 0.15005260705947876"/>
      </geometry>
    </visual>
    <collision>
      <origin rpy="1.524422486909316e-06 -0.19198594987392426 -5.587070859291998e-07" xyz="0.0023382222835841016 -0.02017780003256142 -0.010105537780393803"/>
      <geometry>
        <mesh filename="file://collisions/COL_obj_forearm.R_convex_hull.dae" scale="0.15005260705947876 0.15005260705947876 0.15005260705947876"/>
      </geometry>
    </collision>
  </link>
  <link name="wrist.R_link">
    <inertial>
      <mass value="1" />
      <inertia ixx="0" iyy="0" izz="0" ixy="0" ixz="0" iyz="0" />
    </inertial>
    <visual>
      <origin rpy="1.4703948636451969e-06 2.3841937490942655e-07 -5.422495519269432e-07" xyz="-0.0004945296796213944 -0.003277532204291056 5.291853900961591e-06"/>
      <geometry>
        <mesh filename="file://meshes/obj_wrist.R.dae" scale="0.15005260705947876 0.15005260705947876 0.15005262494714344"/>
      </geometry>
    </visual>
    <collision>
      <origin rpy="1.4703948636451969e-06 2.3841937490942655e-07 -5.422495519269432e-07" xyz="-0.0004945296796213944 -0.003277532204291056 5.291853900961591e-06"/>
      <geometry>
        <mesh filename="file://collisions/COL_obj_wrist.R_convex_hull.dae" scale="0.15005260705947876 0.15005260705947876 0.15005262494714344"/>
      </geometry>
    </collision>
  </link>
  <link name="spine.001_link">
    <inertial>
      <mass value="1" />
      <inertia ixx="0" iyy="0" izz="0" ixy="0" ixz="0" iyz="0" />
    </inertial>
    <visual>
      <origin rpy="1.367517825201503e-06 4.200884688998485e-07 -5.364405524233007e-07" xyz="-0.00015757079615909275 0.03726737525212798 -0.003599170023457776"/>
      <geometry>
        <mesh filename="file://meshes/obj_spine.001.dae" scale="0.15005260705947876 0.15005260705947876 0.15005260705947876"/>
      </geometry>
    </visual>
    <collision>
      <origin rpy="1.367517825201503e-06 4.200884688998485e-07 -5.364405524233007e-07" xyz="-0.00015757079615909275 0.03726737525212798 -0.003599170023457776"/>
      <geometry>
        <mesh filename="file://collisions/COL_obj_spine.001_convex_hull.dae" scale="0.15005260705947876 0.15005260705947876 0.15005260705947876"/>
      </geometry>
    </collision>
  </link>
  <link name="thigh.L_link">
    <inertial>
      <mass value="1" />
      <inertia ixx="0" iyy="0" izz="0" ixy="0" ixz="0" iyz="0" />
    </inertial>
    <visual>
      <origin rpy="1.3827558404955198e-06 4.200882699478825e-07 -5.438911330202245e-07" xyz="0.004078678222230181 -0.025298307272954013 -0.006911292219834442"/>
      <geometry>
        <mesh filename="file://meshes/obj_thigh.L.dae" scale="0.15005260705947876 0.15005260705947876 0.15005264283480813"/>
      </geometry>
    </visual>
    <collision>
      <origin rpy="1.3827558404955198e-06 4.200882699478825e-07 -5.438911330202245e-07" xyz="0.004078678222230181 -0.025298307272954013 -0.006911292219834442"/>
      <geometry>
        <mesh filename="file://collisions/COL_obj_thigh.L_convex_hull.dae" scale="0.15005260705947876 0.15005260705947876 0.15005264283480813"/>
      </geometry>
    </collision>
  </link>
  <link name="shin.L_link">
    <inertial>
      <mass value="1" />
      <inertia ixx="0" iyy="0" izz="0" ixy="0" ixz="0" iyz="0" />
    </inertial>
    <visual>
      <origin rpy="1.3946068975201342e-06 4.200884688998485e-07 -5.401658427217626e-07" xyz="-0.0019899058510272627 0.02815319420803597 -0.018770921789510453"/>
      <geometry>
        <mesh filename="file://meshes/obj_shin.L.dae" scale="0.15005260705947876 0.15005260705947876 0.15005264283480813"/>
      </geometry>
    </visual>
    <collision>
      <origin rpy="1.3946068975201342e-06 4.200884688998485e-07 -5.401658427217626e-07" xyz="-0.0019899058510272627 0.02815319420803597 -0.018770921789510453"/>
      <geometry>
        <mesh filename="file://collisions/COL_obj_shin.L_convex_hull.dae" scale="0.15005260705947876 0.15005260705947876 0.15005264283480813"/>
      </geometry>
    </collision>
  </link>
  <link name="shin_lower.L_link">
    <inertial>
      <mass value="1" />
      <inertia ixx="0" iyy="0" izz="0" ixy="0" ixz="0" iyz="0" />
    </inertial>
    <visual>
      <origin rpy="1.4332094906421844e-06 4.200887246952334e-07 -5.364406092667195e-07" xyz="0.0013721648540285236 -0.0224245331999251 -0.0013075512552571111"/>
      <geometry>
        <mesh filename="file://meshes/obj_shin_lower.L.dae" scale="0.15005260705947876 0.15005260705947876 0.15005260705947876"/>
      </geometry>
    </visual>
    <collision>
      <origin rpy="1.4332094906421844e-06 4.200887246952334e-07 -5.364406092667195e-07" xyz="0.0013721648540285236 -0.0224245331999251 -0.0013075512552571111"/>
      <geometry>
        <mesh filename="file://collisions/COL_obj_shin_lower.L_convex_hull.dae" scale="0.15005260705947876 0.15005260705947876 0.15005260705947876"/>
      </geometry>
    </collision>
  </link>
  <link name="thigh.R_link">
    <inertial>
      <mass value="1" />
      <inertia ixx="0" iyy="0" izz="0" ixy="0" ixz="0" iyz="0" />
    </inertial>
    <visual>
      <origin rpy="1.3678549066753476e-06 4.200882699478825e-07 -5.364405524233007e-07" xyz="-0.004155085381922774 -0.025156885160013687 -0.0069857731016365054"/>
      <geometry>
        <mesh filename="file://meshes/obj_thigh.R.dae" scale="0.15005260705947876 0.15005260705947876 0.15005264283480813"/>
      </geometry>
    </visual>
    <collision>
      <origin rpy="1.3678549066753476e-06 4.200882699478825e-07 -5.364405524233007e-07" xyz="-0.004155085381922774 -0.025156885160013687 -0.0069857731016365054"/>
      <geometry>
        <mesh filename="file://collisions/COL_obj_thigh.R_convex_hull.dae" scale="0.15005260705947876 0.15005260705947876 0.15005264283480813"/>
      </geometry>
    </collision>
  </link>
  <link name="shin.R_link">
    <inertial>
      <mass value="1" />
      <inertia ixx="0" iyy="0" izz="0" ixy="0" ixz="0" iyz="0" />
    </inertial>
    <visual>
      <origin rpy="1.3797056226394488e-06 4.200884404781391e-07 -5.327153189682576e-07" xyz="0.0019365461087941793 0.028146074917492214 -0.018766127895375462"/>
      <geometry>
        <mesh filename="file://meshes/obj_shin.R.dae" scale="0.15005260705947876 0.15005260705947876 0.15005264283480813"/>
      </geometry>
    </visual>
    <collision>
      <origin rpy="1.3797056226394488e-06 4.200884404781391e-07 -5.327153189682576e-07" xyz="0.0019365461087941793 0.028146074917492214 -0.018766127895375462"/>
      <geometry>
        <mesh filename="file://collisions/COL_obj_shin.R_convex_hull.dae" scale="0.15005260705947876 0.15005260705947876 0.15005264283480813"/>
      </geometry>
    </collision>
  </link>
  <link name="shin_lower.R_link">
    <inertial>
      <mass value="1" />
      <inertia ixx="0" iyy="0" izz="0" ixy="0" ixz="0" iyz="0" />
    </inertial>
    <visual>
      <origin rpy="1.4257590237320983e-06 4.2008869627352396e-07 -5.401657858783437e-07" xyz="-0.0011743633374608486 -0.02240531290422343 -0.001300414636038194"/>
      <geometry>
        <mesh filename="file://meshes/obj_shin_lower.R.dae" scale="0.15005260705947876 0.15005260705947876 0.15005260705947876"/>
      </geometry>
    </visual>
    <collision>
      <origin rpy="1.4257590237320983e-06 4.2008869627352396e-07 -5.401657858783437e-07" xyz="-0.0011743633374608486 -0.02240531290422343 -0.001300414636038194"/>
      <geometry>
        <mesh filename="file://collisions/COL_obj_shin_lower.R_convex_hull.dae" scale="0.15005260705947876 0.15005260705947876 0.15005260705947876"/>
      </geometry>
    </collision>
  </link>
  <gazebo>
    <plugin filename="libgeneric_controller_plugin.so" name="generic_controller">
      <controller joint_name="hips.001">
        <type>position</type>
        <pid>100 1 1</pid>
      </controller>
      <controller joint_name="joint_1_obj_hips.002">
        <type>position</type>
        <pid>100 1 1</pid>
      </controller>
      <controller joint_name="hips.002">
        <type>position</type>
        <pid>100 1 1</pid>
      </controller>
      <controller joint_name="joint_1_obj_hips.003">
        <type>position</type>
        <pid>100 1 1</pid>
      </controller>
      <controller joint_name="hips.003">
        <type>position</type>
        <pid>100 1 1</pid>
      </controller>
      <controller joint_name="joint_1_obj_hips.004">
        <type>position</type>
        <pid>100 1 1</pid>
      </controller>
      <controller joint_name="hips.004">
        <type>position</type>
        <pid>100 1 1</pid>
      </controller>
      <controller joint_name="joint_1_obj_hips.005">
        <type>position</type>
        <pid>100 1 1</pid>
      </controller>
      <controller joint_name="hips.005">
        <type>position</type>
        <pid>100 1 1</pid>
      </controller>
      <controller joint_name="joint_1_obj_hips.006">
        <type>position</type>
        <pid>100 1 1</pid>
      </controller>
      <controller joint_name="hips.006">
        <type>position</type>
        <pid>100 1 1</pid>
      </controller>
      <controller joint_name="joint_1_obj_hips.007">
        <type>position</type>
        <pid>100 1 1</pid>
      </controller>
      <controller joint_name="hips.007">
        <type>position</type>
        <pid>100 1 1</pid>
      </controller>
      <controller joint_name="joint_1_obj_hips.008">
        <type>position</type>
        <pid>100 1 1</pid>
      </controller>
      <controller joint_name="hips.008">
        <type>position</type>
        <pid>100 1 1</pid>
      </controller>
      <controller joint_name="joint_1_obj_hips.009">
        <type>position</type>
        <pid>100 1 1</pid>
      </controller>
      <controller joint_name="hips.009">
        <type>position</type>
        <pid>100 1 1</pid>
      </controller>
      <controller joint_name="joint_1_obj_hips.010">
        <type>position</type>
        <pid>100 1 1</pid>
      </controller>
      <controller joint_name="hips.010">
        <type>position</type>
        <pid>100 1 1</pid>
      </controller>
      <controller joint_name="joint_1_obj_hips.011">
        <type>position</type>
        <pid>100 1 1</pid>
      </controller>
      <controller joint_name="hips.011">
        <type>position</type>
        <pid>100 1 1</pid>
      </controller>
      <controller joint_name="joint_1_obj_hips.012">
        <type>position</type>
        <pid>100 1 1</pid>
      </controller>
      <controller joint_name="hips.012">
        <type>position</type>
        <pid>100 1 1</pid>
      </controller>
      <controller joint_name="joint_1_obj_hips.013">
        <type>position</type>
        <pid>100 1 1</pid>
      </controller>
      <controller joint_name="hips.013">
        <type>position</type>
        <pid>100 1 1</pid>
      </controller>
      <controller joint_name="joint_1_obj_hips.014">
        <type>position</type>
        <pid>100 1 1</pid>
      </controller>
      <controller joint_name="hips.014">
        <type>position</type>
        <pid>100 1 1</pid>
      </controller>
      <controller joint_name="joint_1_obj_hips.015">
        <type>position</type>
        <pid>100 1 1</pid>
      </controller>
      <controller joint_name="hips.015">
        <type>position</type>
        <pid>100 1 1</pid>
      </controller>
      <controller joint_name="joint_1_obj_hips.016">
        <type>position</type>
        <pid>100 1 1</pid>
      </controller>
      <controller joint_name="hips.016">
        <type>position</type>
        <pid>100 1 1</pid>
      </controller>
      <controller joint_name="joint_1_obj_hips.017">
        <type>position</type>
        <pid>100 1 1</pid>
      </controller>
      <controller joint_name="hips.017">
        <type>position</type>
        <pid>100 1 1</pid>
      </controller>
      <controller joint_name="joint_1_obj_hips.018">
        <type>position</type>
        <pid>100 1 1</pid>
      </controller>
      <controller joint_name="hips.018">
        <type>position</type>
        <pid>100 1 1</pid>
      </controller>
      <controller joint_name="joint_1_obj_hips.019">
        <type>position</type>
        <pid>100 1 1</pid>
      </controller>
      <controller joint_name="hips.019">
        <type>position</type>
        <pid>100 1 1</pid>
      </controller>
      <controller joint_name="joint_1_obj_hips.020">
        <type>position</type>
        <pid>100 1 1</pid>
      </controller>
      <controller joint_name="hips.020">
        <type>position</type>
        <pid>100 1 1</pid>
      </controller>
      <controller joint_name="joint_1_obj_hips.021">
        <type>position</type>
        <pid>100 1 1</pid>
      </controller>
      <controller joint_name="hips.021">
        <type>position</type>
        <pid>100 1 1</pid>
      </controller>
      <controller joint_name="hips">
        <type>position</type>
        <pid>100 1 1</pid>
      </controller>
      <controller joint_name="spine">
        <type>position</type>
        <pid>100 1 1</pid>
      </controller>
      <controller joint_name="chest">
        <type>position</type>
        <pid>100 1 1</pid>
      </controller>
      <controller joint_name="neck">
        <type>position</type>
        <pid>100 1 1</pid>
      </controller>
      <controller joint_name="head">
        <type>position</type>
        <pid>100 1 1</pid>
      </controller>
      <controller joint_name="nose">
        <type>position</type>
        <pid>100 1 1</pid>
      </controller>
      <controller joint_name="mouth">
        <type>position</type>
        <pid>100 1 1</pid>
      </controller>
      <controller joint_name="neck.001">
        <type>position</type>
        <pid>100 1 1</pid>
      </controller>
      <controller joint_name="neck.002">
        <type>position</type>
        <pid>100 1 1</pid>
      </controller>
      <controller joint_name="shoulder.L">
        <type>position</type>
        <pid>100 1 1</pid>
      </controller>
      <controller joint_name="upper_arm.L">
        <type>position</type>
        <pid>100 1 1</pid>
      </controller>
      <controller joint_name="forearm.L">
        <type>position</type>
        <pid>100 1 1</pid>
      </controller>
      <controller joint_name="wrist.L">
        <type>position</type>
        <pid>100 1 1</pid>
      </controller>
      <controller joint_name="shoulder.R">
        <type>position</type>
        <pid>100 1 1</pid>
      </controller>
      <controller joint_name="upper_arm.R">
        <type>position</type>
        <pid>100 1 1</pid>
      </controller>
      <controller joint_name="forearm.R">
        <type>position</type>
        <pid>100 1 1</pid>
      </controller>
      <controller joint_name="wrist.R">
        <type>position</type>
        <pid>100 1 1</pid>
      </controller>
      <controller joint_name="spine.001">
        <type>position</type>
        <pid>100 1 1</pid>
      </controller>
      <controller joint_name="thigh.L">
        <type>position</type>
        <pid>100 1 1</pid>
      </controller>
      <controller joint_name="shin.L">
        <type>position</type>
        <pid>100 1 1</pid>
      </controller>
      <controller joint_name="shin_lower.L">
        <type>position</type>
        <pid>100 1 1</pid>
      </controller>
      <controller joint_name="thigh.R">
        <type>position</type>
        <pid>100 1 1</pid>
      </controller>
      <controller joint_name="shin.R">
        <type>position</type>
        <pid>100 1 1</pid>
      </controller>
      <controller joint_name="shin_lower.R">
        <type>position</type>
        <pid>100 1 1</pid>
      </controller>
    </plugin>
  </gazebo>
</robot>
